 * Serving Flask app 'base' (lazy loading)
 * Environment: production
   WARNING: This is a development server. Do not use it in a production deployment.
   Use a production WSGI server instead.
 * Debug mode: on
 * Running on http://127.0.0.1:50000/ (Press CTRL+C to quit)
 * Restarting with stat
 * Debugger is active!
 * Debugger PIN: 655-285-932
 * Serving Flask app 'base' (lazy loading)
 * Environment: production
   WARNING: This is a development server. Do not use it in a production deployment.
   Use a production WSGI server instead.
 * Debug mode: on
Traceback (most recent call last):
  File "/Users/user/Documents/python/AstreinteFinale/base.py", line 417, in <module>
    app.run(debug=True, host="127.0.0.1",port=50000)
  File "/Users/user/Documents/python/AstreinteFinale/venv/lib/python3.10/site-packages/flask/app.py", line 920, in run
    run_simple(t.cast(str, host), port, self, **options)
  File "/Users/user/Documents/python/AstreinteFinale/venv/lib/python3.10/site-packages/werkzeug/serving.py", line 984, in run_simple
    s.bind(server_address)
OSError: [Errno 48] Address already in use
 * Serving Flask app 'base' (lazy loading)
 * Environment: production
   WARNING: This is a development server. Do not use it in a production deployment.
   Use a production WSGI server instead.
 * Debug mode: on
Traceback (most recent call last):
  File "/Users/user/Documents/python/AstreinteFinale/base.py", line 417, in <module>
    app.run(debug=True, host="127.0.0.1",port=50000)
  File "/Users/user/Documents/python/AstreinteFinale/venv/lib/python3.10/site-packages/flask/app.py", line 920, in run
    run_simple(t.cast(str, host), port, self, **options)
  File "/Users/user/Documents/python/AstreinteFinale/venv/lib/python3.10/site-packages/werkzeug/serving.py", line 984, in run_simple
    s.bind(server_address)
OSError: [Errno 48] Address already in use
 * Serving Flask app 'base' (lazy loading)
 * Environment: production
   WARNING: This is a development server. Do not use it in a production deployment.
   Use a production WSGI server instead.
 * Debug mode: on
Traceback (most recent call last):
  File "/Users/user/Documents/python/AstreinteFinale/base.py", line 417, in <module>
    app.run(debug=True, host="127.0.0.1",port=50000)
  File "/Users/user/Documents/python/AstreinteFinale/venv/lib/python3.10/site-packages/flask/app.py", line 920, in run
    run_simple(t.cast(str, host), port, self, **options)
  File "/Users/user/Documents/python/AstreinteFinale/venv/lib/python3.10/site-packages/werkzeug/serving.py", line 984, in run_simple
    s.bind(server_address)
OSError: [Errno 48] Address already in use
 * Serving Flask app 'base' (lazy loading)
 * Environment: production
   WARNING: This is a development server. Do not use it in a production deployment.
   Use a production WSGI server instead.
 * Debug mode: on
Traceback (most recent call last):
  File "/Users/user/Documents/python/AstreinteFinale/base.py", line 417, in <module>
    app.run(debug=True, host="127.0.0.1",port=50000)
  File "/Users/user/Documents/python/AstreinteFinale/venv/lib/python3.10/site-packages/flask/app.py", line 920, in run
    run_simple(t.cast(str, host), port, self, **options)
  File "/Users/user/Documents/python/AstreinteFinale/venv/lib/python3.10/site-packages/werkzeug/serving.py", line 984, in run_simple
    s.bind(server_address)
OSError: [Errno 48] Address already in use
 * Serving Flask app 'base' (lazy loading)
 * Environment: production
   WARNING: This is a development server. Do not use it in a production deployment.
   Use a production WSGI server instead.
 * Debug mode: on
Traceback (most recent call last):
  File "/Users/user/Documents/python/AstreinteFinale/base.py", line 417, in <module>
    app.run(debug=True, host="127.0.0.1",port=50000)
  File "/Users/user/Documents/python/AstreinteFinale/venv/lib/python3.10/site-packages/flask/app.py", line 920, in run
    run_simple(t.cast(str, host), port, self, **options)
  File "/Users/user/Documents/python/AstreinteFinale/venv/lib/python3.10/site-packages/werkzeug/serving.py", line 984, in run_simple
    s.bind(server_address)
OSError: [Errno 48] Address already in use
 * Serving Flask app 'base' (lazy loading)
 * Environment: production
   WARNING: This is a development server. Do not use it in a production deployment.
   Use a production WSGI server instead.
 * Debug mode: on
Traceback (most recent call last):
  File "/Users/user/Documents/python/AstreinteFinale/base.py", line 417, in <module>
    app.run(debug=True, host="127.0.0.1",port=50000)
  File "/Users/user/Documents/python/AstreinteFinale/venv/lib/python3.10/site-packages/flask/app.py", line 920, in run
    run_simple(t.cast(str, host), port, self, **options)
  File "/Users/user/Documents/python/AstreinteFinale/venv/lib/python3.10/site-packages/werkzeug/serving.py", line 984, in run_simple
    s.bind(server_address)
OSError: [Errno 48] Address already in use
 * Serving Flask app 'base' (lazy loading)
 * Environment: production
   WARNING: This is a development server. Do not use it in a production deployment.
   Use a production WSGI server instead.
 * Debug mode: on
Traceback (most recent call last):
  File "/Users/user/Documents/python/AstreinteFinale/base.py", line 417, in <module>
    app.run(debug=True, host="127.0.0.1",port=50000)
  File "/Users/user/Documents/python/AstreinteFinale/venv/lib/python3.10/site-packages/flask/app.py", line 920, in run
    run_simple(t.cast(str, host), port, self, **options)
  File "/Users/user/Documents/python/AstreinteFinale/venv/lib/python3.10/site-packages/werkzeug/serving.py", line 984, in run_simple
    s.bind(server_address)
OSError: [Errno 48] Address already in use
 * Serving Flask app 'base' (lazy loading)
 * Environment: production
   WARNING: This is a development server. Do not use it in a production deployment.
   Use a production WSGI server instead.
 * Debug mode: on
Traceback (most recent call last):
  File "/Users/user/Documents/python/AstreinteFinale/base.py", line 417, in <module>
    app.run(debug=True, host="127.0.0.1",port=50000)
  File "/Users/user/Documents/python/AstreinteFinale/venv/lib/python3.10/site-packages/flask/app.py", line 920, in run
    run_simple(t.cast(str, host), port, self, **options)
  File "/Users/user/Documents/python/AstreinteFinale/venv/lib/python3.10/site-packages/werkzeug/serving.py", line 984, in run_simple
    s.bind(server_address)
OSError: [Errno 48] Address already in use
 * Serving Flask app 'base' (lazy loading)
 * Environment: production
   WARNING: This is a development server. Do not use it in a production deployment.
   Use a production WSGI server instead.
 * Debug mode: on
Traceback (most recent call last):
  File "/Users/user/Documents/python/AstreinteFinale/base.py", line 417, in <module>
    app.run(debug=True, host="127.0.0.1",port=50000)
  File "/Users/user/Documents/python/AstreinteFinale/venv/lib/python3.10/site-packages/flask/app.py", line 920, in run
    run_simple(t.cast(str, host), port, self, **options)
  File "/Users/user/Documents/python/AstreinteFinale/venv/lib/python3.10/site-packages/werkzeug/serving.py", line 984, in run_simple
    s.bind(server_address)
OSError: [Errno 48] Address already in use
 * Serving Flask app 'base' (lazy loading)
 * Environment: production
   WARNING: This is a development server. Do not use it in a production deployment.
   Use a production WSGI server instead.
 * Debug mode: on
Traceback (most recent call last):
  File "/Users/user/Documents/python/AstreinteFinale/base.py", line 417, in <module>
    app.run(debug=True, host="127.0.0.1",port=50000)
  File "/Users/user/Documents/python/AstreinteFinale/venv/lib/python3.10/site-packages/flask/app.py", line 920, in run
    run_simple(t.cast(str, host), port, self, **options)
  File "/Users/user/Documents/python/AstreinteFinale/venv/lib/python3.10/site-packages/werkzeug/serving.py", line 984, in run_simple
    s.bind(server_address)
OSError: [Errno 48] Address already in use
 * Serving Flask app 'base' (lazy loading)
 * Environment: production
   WARNING: This is a development server. Do not use it in a production deployment.
   Use a production WSGI server instead.
 * Debug mode: on
Traceback (most recent call last):
  File "/Users/user/Documents/python/AstreinteFinale/base.py", line 417, in <module>
    app.run(debug=True, host="127.0.0.1",port=50000)
  File "/Users/user/Documents/python/AstreinteFinale/venv/lib/python3.10/site-packages/flask/app.py", line 920, in run
    run_simple(t.cast(str, host), port, self, **options)
  File "/Users/user/Documents/python/AstreinteFinale/venv/lib/python3.10/site-packages/werkzeug/serving.py", line 984, in run_simple
    s.bind(server_address)
OSError: [Errno 48] Address already in use
 * Serving Flask app 'base' (lazy loading)
 * Environment: production
   WARNING: This is a development server. Do not use it in a production deployment.
   Use a production WSGI server instead.
 * Debug mode: on
Traceback (most recent call last):
  File "/Users/user/Documents/python/AstreinteFinale/base.py", line 417, in <module>
    app.run(debug=True, host="127.0.0.1",port=50000)
  File "/Users/user/Documents/python/AstreinteFinale/venv/lib/python3.10/site-packages/flask/app.py", line 920, in run
    run_simple(t.cast(str, host), port, self, **options)
  File "/Users/user/Documents/python/AstreinteFinale/venv/lib/python3.10/site-packages/werkzeug/serving.py", line 984, in run_simple
    s.bind(server_address)
OSError: [Errno 48] Address already in use
 * Serving Flask app 'base' (lazy loading)
 * Environment: production
   WARNING: This is a development server. Do not use it in a production deployment.
   Use a production WSGI server instead.
 * Debug mode: on
Traceback (most recent call last):
  File "/Users/user/Documents/python/AstreinteFinale/base.py", line 417, in <module>
    app.run(debug=True, host="127.0.0.1",port=50000)
  File "/Users/user/Documents/python/AstreinteFinale/venv/lib/python3.10/site-packages/flask/app.py", line 920, in run
    run_simple(t.cast(str, host), port, self, **options)
  File "/Users/user/Documents/python/AstreinteFinale/venv/lib/python3.10/site-packages/werkzeug/serving.py", line 984, in run_simple
    s.bind(server_address)
OSError: [Errno 48] Address already in use
 * Serving Flask app 'base' (lazy loading)
 * Environment: production
   WARNING: This is a development server. Do not use it in a production deployment.
   Use a production WSGI server instead.
 * Debug mode: on
Traceback (most recent call last):
  File "/Users/user/Documents/python/AstreinteFinale/base.py", line 417, in <module>
    app.run(debug=True, host="127.0.0.1",port=50000)
  File "/Users/user/Documents/python/AstreinteFinale/venv/lib/python3.10/site-packages/flask/app.py", line 920, in run
    run_simple(t.cast(str, host), port, self, **options)
  File "/Users/user/Documents/python/AstreinteFinale/venv/lib/python3.10/site-packages/werkzeug/serving.py", line 984, in run_simple
    s.bind(server_address)
OSError: [Errno 48] Address already in use
 * Serving Flask app 'base' (lazy loading)
 * Environment: production
   WARNING: This is a development server. Do not use it in a production deployment.
   Use a production WSGI server instead.
 * Debug mode: on
Traceback (most recent call last):
  File "/Users/user/Documents/python/AstreinteFinale/base.py", line 417, in <module>
    app.run(debug=True, host="127.0.0.1",port=50000)
  File "/Users/user/Documents/python/AstreinteFinale/venv/lib/python3.10/site-packages/flask/app.py", line 920, in run
    run_simple(t.cast(str, host), port, self, **options)
  File "/Users/user/Documents/python/AstreinteFinale/venv/lib/python3.10/site-packages/werkzeug/serving.py", line 984, in run_simple
    s.bind(server_address)
OSError: [Errno 48] Address already in use
 * Serving Flask app 'base' (lazy loading)
 * Environment: production
   WARNING: This is a development server. Do not use it in a production deployment.
   Use a production WSGI server instead.
 * Debug mode: on
Traceback (most recent call last):
  File "/Users/user/Documents/python/AstreinteFinale/base.py", line 417, in <module>
    app.run(debug=True, host="127.0.0.1",port=50000)
  File "/Users/user/Documents/python/AstreinteFinale/venv/lib/python3.10/site-packages/flask/app.py", line 920, in run
    run_simple(t.cast(str, host), port, self, **options)
  File "/Users/user/Documents/python/AstreinteFinale/venv/lib/python3.10/site-packages/werkzeug/serving.py", line 984, in run_simple
    s.bind(server_address)
OSError: [Errno 48] Address already in use
 * Serving Flask app 'base' (lazy loading)
 * Environment: production
   WARNING: This is a development server. Do not use it in a production deployment.
   Use a production WSGI server instead.
 * Debug mode: on
Traceback (most recent call last):
  File "/Users/user/Documents/python/AstreinteFinale/base.py", line 417, in <module>
    app.run(debug=True, host="127.0.0.1",port=50000)
  File "/Users/user/Documents/python/AstreinteFinale/venv/lib/python3.10/site-packages/flask/app.py", line 920, in run
    run_simple(t.cast(str, host), port, self, **options)
  File "/Users/user/Documents/python/AstreinteFinale/venv/lib/python3.10/site-packages/werkzeug/serving.py", line 984, in run_simple
    s.bind(server_address)
OSError: [Errno 48] Address already in use
 * Serving Flask app 'base' (lazy loading)
 * Environment: production
   WARNING: This is a development server. Do not use it in a production deployment.
   Use a production WSGI server instead.
 * Debug mode: on
Traceback (most recent call last):
  File "/Users/user/Documents/python/AstreinteFinale/base.py", line 417, in <module>
    app.run(debug=True, host="127.0.0.1",port=50000)
  File "/Users/user/Documents/python/AstreinteFinale/venv/lib/python3.10/site-packages/flask/app.py", line 920, in run
    run_simple(t.cast(str, host), port, self, **options)
  File "/Users/user/Documents/python/AstreinteFinale/venv/lib/python3.10/site-packages/werkzeug/serving.py", line 984, in run_simple
    s.bind(server_address)
OSError: [Errno 48] Address already in use
 * Serving Flask app 'base' (lazy loading)
 * Environment: production
   WARNING: This is a development server. Do not use it in a production deployment.
   Use a production WSGI server instead.
 * Debug mode: on
Traceback (most recent call last):
  File "/Users/user/Documents/python/AstreinteFinale/base.py", line 417, in <module>
    app.run(debug=True, host="127.0.0.1",port=50000)
  File "/Users/user/Documents/python/AstreinteFinale/venv/lib/python3.10/site-packages/flask/app.py", line 920, in run
    run_simple(t.cast(str, host), port, self, **options)
  File "/Users/user/Documents/python/AstreinteFinale/venv/lib/python3.10/site-packages/werkzeug/serving.py", line 984, in run_simple
    s.bind(server_address)
OSError: [Errno 48] Address already in use
 * Serving Flask app 'base' (lazy loading)
 * Environment: production
   WARNING: This is a development server. Do not use it in a production deployment.
   Use a production WSGI server instead.
 * Debug mode: on
Traceback (most recent call last):
  File "/Users/user/Documents/python/AstreinteFinale/base.py", line 417, in <module>
    app.run(debug=True, host="127.0.0.1",port=50000)
  File "/Users/user/Documents/python/AstreinteFinale/venv/lib/python3.10/site-packages/flask/app.py", line 920, in run
    run_simple(t.cast(str, host), port, self, **options)
  File "/Users/user/Documents/python/AstreinteFinale/venv/lib/python3.10/site-packages/werkzeug/serving.py", line 984, in run_simple
    s.bind(server_address)
OSError: [Errno 48] Address already in use
 * Serving Flask app 'base' (lazy loading)
 * Environment: production
   WARNING: This is a development server. Do not use it in a production deployment.
   Use a production WSGI server instead.
 * Debug mode: on
Traceback (most recent call last):
  File "/Users/user/Documents/python/AstreinteFinale/base.py", line 417, in <module>
    app.run(debug=True, host="127.0.0.1",port=50000)
  File "/Users/user/Documents/python/AstreinteFinale/venv/lib/python3.10/site-packages/flask/app.py", line 920, in run
    run_simple(t.cast(str, host), port, self, **options)
  File "/Users/user/Documents/python/AstreinteFinale/venv/lib/python3.10/site-packages/werkzeug/serving.py", line 984, in run_simple
    s.bind(server_address)
OSError: [Errno 48] Address already in use
 * Serving Flask app 'base' (lazy loading)
 * Environment: production
   WARNING: This is a development server. Do not use it in a production deployment.
   Use a production WSGI server instead.
 * Debug mode: on
Traceback (most recent call last):
  File "/Users/user/Documents/python/AstreinteFinale/base.py", line 417, in <module>
    app.run(debug=True, host="127.0.0.1",port=50000)
  File "/Users/user/Documents/python/AstreinteFinale/venv/lib/python3.10/site-packages/flask/app.py", line 920, in run
    run_simple(t.cast(str, host), port, self, **options)
  File "/Users/user/Documents/python/AstreinteFinale/venv/lib/python3.10/site-packages/werkzeug/serving.py", line 984, in run_simple
    s.bind(server_address)
OSError: [Errno 48] Address already in use
 * Detected change in '/Users/user/Documents/python/AstreinteFinale/base.py', reloading
 * Restarting with stat
 * Serving Flask app 'base' (lazy loading)
 * Environment: production
   WARNING: This is a development server. Do not use it in a production deployment.
   Use a production WSGI server instead.
 * Debug mode: on
 * Debugger is active!
 * Running on http://127.0.0.1:5000/ (Press CTRL+C to quit)
 * Debugger PIN: 655-285-932
 * Restarting with stat
 * Debugger is active!
 * Debugger PIN: 655-285-932
 * Serving Flask app 'base' (lazy loading)
 * Environment: production
   WARNING: This is a development server. Do not use it in a production deployment.
   Use a production WSGI server instead.
 * Debug mode: on
Traceback (most recent call last):
  File "/Users/user/Documents/python/AstreinteFinale/base.py", line 417, in <module>
    app.run(debug=True, host="127.0.0.1",port=5000)
  File "/Users/user/Documents/python/AstreinteFinale/venv/lib/python3.10/site-packages/flask/app.py", line 920, in run
    run_simple(t.cast(str, host), port, self, **options)
  File "/Users/user/Documents/python/AstreinteFinale/venv/lib/python3.10/site-packages/werkzeug/serving.py", line 984, in run_simple
    s.bind(server_address)
OSError: [Errno 48] Address already in use
127.0.0.1 - - [03/Jan/2022 10:08:25] "GET /astreintes HTTP/1.1" 200 -
 * Serving Flask app 'base' (lazy loading)
 * Environment: production
   WARNING: This is a development server. Do not use it in a production deployment.
   Use a production WSGI server instead.
 * Debug mode: on
Traceback (most recent call last):
  File "/Users/user/Documents/python/AstreinteFinale/base.py", line 417, in <module>
    app.run(debug=True, host="127.0.0.1",port=5000)
  File "/Users/user/Documents/python/AstreinteFinale/venv/lib/python3.10/site-packages/flask/app.py", line 920, in run
    run_simple(t.cast(str, host), port, self, **options)
  File "/Users/user/Documents/python/AstreinteFinale/venv/lib/python3.10/site-packages/werkzeug/serving.py", line 984, in run_simple
    s.bind(server_address)
OSError: [Errno 48] Address already in use
 * Serving Flask app 'base' (lazy loading)
 * Environment: production
   WARNING: This is a development server. Do not use it in a production deployment.
   Use a production WSGI server instead.
 * Debug mode: on
Traceback (most recent call last):
  File "/Users/user/Documents/python/AstreinteFinale/base.py", line 417, in <module>
    app.run(debug=True, host="127.0.0.1",port=5000)
  File "/Users/user/Documents/python/AstreinteFinale/venv/lib/python3.10/site-packages/flask/app.py", line 920, in run
    run_simple(t.cast(str, host), port, self, **options)
  File "/Users/user/Documents/python/AstreinteFinale/venv/lib/python3.10/site-packages/werkzeug/serving.py", line 984, in run_simple
    s.bind(server_address)
OSError: [Errno 48] Address already in use
127.0.0.1 - - [03/Jan/2022 10:10:09] "GET /astreintes HTTP/1.1" 200 -
 * Serving Flask app 'base' (lazy loading)
 * Environment: production
   WARNING: This is a development server. Do not use it in a production deployment.
   Use a production WSGI server instead.
 * Debug mode: on
Traceback (most recent call last):
  File "/Users/user/Documents/python/AstreinteFinale/base.py", line 417, in <module>
    app.run(debug=True, host="127.0.0.1",port=5000)
  File "/Users/user/Documents/python/AstreinteFinale/venv/lib/python3.10/site-packages/flask/app.py", line 920, in run
    run_simple(t.cast(str, host), port, self, **options)
  File "/Users/user/Documents/python/AstreinteFinale/venv/lib/python3.10/site-packages/werkzeug/serving.py", line 984, in run_simple
    s.bind(server_address)
OSError: [Errno 48] Address already in use
 * Serving Flask app 'base' (lazy loading)
 * Environment: production
   WARNING: This is a development server. Do not use it in a production deployment.
   Use a production WSGI server instead.
 * Debug mode: on
Traceback (most recent call last):
  File "/Users/user/Documents/python/AstreinteFinale/base.py", line 417, in <module>
    app.run(debug=True, host="127.0.0.1",port=5000)
  File "/Users/user/Documents/python/AstreinteFinale/venv/lib/python3.10/site-packages/flask/app.py", line 920, in run
    run_simple(t.cast(str, host), port, self, **options)
  File "/Users/user/Documents/python/AstreinteFinale/venv/lib/python3.10/site-packages/werkzeug/serving.py", line 984, in run_simple
    s.bind(server_address)
OSError: [Errno 48] Address already in use
127.0.0.1 - - [03/Jan/2022 10:12:10] "GET /astreintes HTTP/1.1" 200 -
 * Serving Flask app 'base' (lazy loading)
 * Environment: production
   WARNING: This is a development server. Do not use it in a production deployment.
   Use a production WSGI server instead.
 * Debug mode: on
Traceback (most recent call last):
  File "/Users/user/Documents/python/AstreinteFinale/base.py", line 417, in <module>
    app.run(debug=True, host="127.0.0.1",port=5000)
  File "/Users/user/Documents/python/AstreinteFinale/venv/lib/python3.10/site-packages/flask/app.py", line 920, in run
    run_simple(t.cast(str, host), port, self, **options)
  File "/Users/user/Documents/python/AstreinteFinale/venv/lib/python3.10/site-packages/werkzeug/serving.py", line 984, in run_simple
    s.bind(server_address)
OSError: [Errno 48] Address already in use
 * Serving Flask app 'base' (lazy loading)
 * Environment: production
   WARNING: This is a development server. Do not use it in a production deployment.
   Use a production WSGI server instead.
 * Debug mode: on
Traceback (most recent call last):
  File "/Users/user/Documents/python/AstreinteFinale/base.py", line 417, in <module>
    app.run(debug=True, host="127.0.0.1",port=5000)
  File "/Users/user/Documents/python/AstreinteFinale/venv/lib/python3.10/site-packages/flask/app.py", line 920, in run
    run_simple(t.cast(str, host), port, self, **options)
  File "/Users/user/Documents/python/AstreinteFinale/venv/lib/python3.10/site-packages/werkzeug/serving.py", line 984, in run_simple
    s.bind(server_address)
OSError: [Errno 48] Address already in use
127.0.0.1 - - [03/Jan/2022 10:14:11] "GET /astreintes HTTP/1.1" 200 -
 * Serving Flask app 'base' (lazy loading)
 * Environment: production
   WARNING: This is a development server. Do not use it in a production deployment.
   Use a production WSGI server instead.
 * Debug mode: on
Traceback (most recent call last):
  File "/Users/user/Documents/python/AstreinteFinale/base.py", line 417, in <module>
    app.run(debug=True, host="127.0.0.1",port=5000)
  File "/Users/user/Documents/python/AstreinteFinale/venv/lib/python3.10/site-packages/flask/app.py", line 920, in run
    run_simple(t.cast(str, host), port, self, **options)
  File "/Users/user/Documents/python/AstreinteFinale/venv/lib/python3.10/site-packages/werkzeug/serving.py", line 984, in run_simple
    s.bind(server_address)
OSError: [Errno 48] Address already in use
 * Serving Flask app 'base' (lazy loading)
 * Environment: production
   WARNING: This is a development server. Do not use it in a production deployment.
   Use a production WSGI server instead.
 * Debug mode: on
Traceback (most recent call last):
  File "/Users/user/Documents/python/AstreinteFinale/base.py", line 417, in <module>
    app.run(debug=True, host="127.0.0.1",port=5000)
  File "/Users/user/Documents/python/AstreinteFinale/venv/lib/python3.10/site-packages/flask/app.py", line 920, in run
    run_simple(t.cast(str, host), port, self, **options)
  File "/Users/user/Documents/python/AstreinteFinale/venv/lib/python3.10/site-packages/werkzeug/serving.py", line 984, in run_simple
    s.bind(server_address)
OSError: [Errno 48] Address already in use
127.0.0.1 - - [03/Jan/2022 10:16:10] "GET /astreintes HTTP/1.1" 200 -
 * Serving Flask app 'base' (lazy loading)
 * Environment: production
   WARNING: This is a development server. Do not use it in a production deployment.
   Use a production WSGI server instead.
 * Debug mode: on
Traceback (most recent call last):
  File "/Users/user/Documents/python/AstreinteFinale/base.py", line 417, in <module>
    app.run(debug=True, host="127.0.0.1",port=5000)
  File "/Users/user/Documents/python/AstreinteFinale/venv/lib/python3.10/site-packages/flask/app.py", line 920, in run
    run_simple(t.cast(str, host), port, self, **options)
  File "/Users/user/Documents/python/AstreinteFinale/venv/lib/python3.10/site-packages/werkzeug/serving.py", line 984, in run_simple
    s.bind(server_address)
OSError: [Errno 48] Address already in use
 * Serving Flask app 'base' (lazy loading)
 * Environment: production
   WARNING: This is a development server. Do not use it in a production deployment.
   Use a production WSGI server instead.
 * Debug mode: on
Traceback (most recent call last):
  File "/Users/user/Documents/python/AstreinteFinale/base.py", line 417, in <module>
    app.run(debug=True, host="127.0.0.1",port=5000)
  File "/Users/user/Documents/python/AstreinteFinale/venv/lib/python3.10/site-packages/flask/app.py", line 920, in run
    run_simple(t.cast(str, host), port, self, **options)
  File "/Users/user/Documents/python/AstreinteFinale/venv/lib/python3.10/site-packages/werkzeug/serving.py", line 984, in run_simple
    s.bind(server_address)
OSError: [Errno 48] Address already in use
127.0.0.1 - - [03/Jan/2022 10:18:10] "GET /astreintes HTTP/1.1" 200 -
 * Serving Flask app 'base' (lazy loading)
 * Environment: production
   WARNING: This is a development server. Do not use it in a production deployment.
   Use a production WSGI server instead.
 * Debug mode: on
Traceback (most recent call last):
  File "/Users/user/Documents/python/AstreinteFinale/base.py", line 417, in <module>
    app.run(debug=True, host="127.0.0.1",port=5000)
  File "/Users/user/Documents/python/AstreinteFinale/venv/lib/python3.10/site-packages/flask/app.py", line 920, in run
    run_simple(t.cast(str, host), port, self, **options)
  File "/Users/user/Documents/python/AstreinteFinale/venv/lib/python3.10/site-packages/werkzeug/serving.py", line 984, in run_simple
    s.bind(server_address)
OSError: [Errno 48] Address already in use
 * Serving Flask app 'base' (lazy loading)
 * Environment: production
   WARNING: This is a development server. Do not use it in a production deployment.
   Use a production WSGI server instead.
 * Debug mode: on
Traceback (most recent call last):
  File "/Users/user/Documents/python/AstreinteFinale/base.py", line 417, in <module>
    app.run(debug=True, host="127.0.0.1",port=5000)
  File "/Users/user/Documents/python/AstreinteFinale/venv/lib/python3.10/site-packages/flask/app.py", line 920, in run
    run_simple(t.cast(str, host), port, self, **options)
  File "/Users/user/Documents/python/AstreinteFinale/venv/lib/python3.10/site-packages/werkzeug/serving.py", line 984, in run_simple
    s.bind(server_address)
OSError: [Errno 48] Address already in use
127.0.0.1 - - [03/Jan/2022 10:20:14] "GET /astreintes HTTP/1.1" 200 -
 * Serving Flask app 'base' (lazy loading)
 * Environment: production
   WARNING: This is a development server. Do not use it in a production deployment.
   Use a production WSGI server instead.
 * Debug mode: on
Traceback (most recent call last):
  File "/Users/user/Documents/python/AstreinteFinale/base.py", line 417, in <module>
    app.run(debug=True, host="127.0.0.1",port=5000)
  File "/Users/user/Documents/python/AstreinteFinale/venv/lib/python3.10/site-packages/flask/app.py", line 920, in run
    run_simple(t.cast(str, host), port, self, **options)
  File "/Users/user/Documents/python/AstreinteFinale/venv/lib/python3.10/site-packages/werkzeug/serving.py", line 984, in run_simple
    s.bind(server_address)
OSError: [Errno 48] Address already in use
 * Serving Flask app 'base' (lazy loading)
 * Environment: production
   WARNING: This is a development server. Do not use it in a production deployment.
   Use a production WSGI server instead.
 * Debug mode: on
Traceback (most recent call last):
  File "/Users/user/Documents/python/AstreinteFinale/base.py", line 417, in <module>
    app.run(debug=True, host="127.0.0.1",port=5000)
  File "/Users/user/Documents/python/AstreinteFinale/venv/lib/python3.10/site-packages/flask/app.py", line 920, in run
    run_simple(t.cast(str, host), port, self, **options)
  File "/Users/user/Documents/python/AstreinteFinale/venv/lib/python3.10/site-packages/werkzeug/serving.py", line 984, in run_simple
    s.bind(server_address)
OSError: [Errno 48] Address already in use
127.0.0.1 - - [03/Jan/2022 10:22:10] "GET /astreintes HTTP/1.1" 200 -
 * Serving Flask app 'base' (lazy loading)
 * Environment: production
   WARNING: This is a development server. Do not use it in a production deployment.
   Use a production WSGI server instead.
 * Debug mode: on
Traceback (most recent call last):
  File "/Users/user/Documents/python/AstreinteFinale/base.py", line 417, in <module>
    app.run(debug=True, host="127.0.0.1",port=5000)
  File "/Users/user/Documents/python/AstreinteFinale/venv/lib/python3.10/site-packages/flask/app.py", line 920, in run
    run_simple(t.cast(str, host), port, self, **options)
  File "/Users/user/Documents/python/AstreinteFinale/venv/lib/python3.10/site-packages/werkzeug/serving.py", line 984, in run_simple
    s.bind(server_address)
OSError: [Errno 48] Address already in use
 * Serving Flask app 'base' (lazy loading)
 * Environment: production
   WARNING: This is a development server. Do not use it in a production deployment.
   Use a production WSGI server instead.
 * Debug mode: on
Traceback (most recent call last):
  File "/Users/user/Documents/python/AstreinteFinale/base.py", line 417, in <module>
    app.run(debug=True, host="127.0.0.1",port=5000)
  File "/Users/user/Documents/python/AstreinteFinale/venv/lib/python3.10/site-packages/flask/app.py", line 920, in run
    run_simple(t.cast(str, host), port, self, **options)
  File "/Users/user/Documents/python/AstreinteFinale/venv/lib/python3.10/site-packages/werkzeug/serving.py", line 984, in run_simple
    s.bind(server_address)
OSError: [Errno 48] Address already in use
127.0.0.1 - - [03/Jan/2022 10:24:11] "GET /astreintes HTTP/1.1" 200 -
 * Serving Flask app 'base' (lazy loading)
 * Environment: production
   WARNING: This is a development server. Do not use it in a production deployment.
   Use a production WSGI server instead.
 * Debug mode: on
Traceback (most recent call last):
  File "/Users/user/Documents/python/AstreinteFinale/base.py", line 417, in <module>
    app.run(debug=True, host="127.0.0.1",port=5000)
  File "/Users/user/Documents/python/AstreinteFinale/venv/lib/python3.10/site-packages/flask/app.py", line 920, in run
    run_simple(t.cast(str, host), port, self, **options)
  File "/Users/user/Documents/python/AstreinteFinale/venv/lib/python3.10/site-packages/werkzeug/serving.py", line 984, in run_simple
    s.bind(server_address)
OSError: [Errno 48] Address already in use
 * Serving Flask app 'base' (lazy loading)
 * Environment: production
   WARNING: This is a development server. Do not use it in a production deployment.
   Use a production WSGI server instead.
 * Debug mode: on
Traceback (most recent call last):
  File "/Users/user/Documents/python/AstreinteFinale/base.py", line 417, in <module>
    app.run(debug=True, host="127.0.0.1",port=5000)
  File "/Users/user/Documents/python/AstreinteFinale/venv/lib/python3.10/site-packages/flask/app.py", line 920, in run
    run_simple(t.cast(str, host), port, self, **options)
  File "/Users/user/Documents/python/AstreinteFinale/venv/lib/python3.10/site-packages/werkzeug/serving.py", line 984, in run_simple
    s.bind(server_address)
OSError: [Errno 48] Address already in use
127.0.0.1 - - [03/Jan/2022 10:26:10] "GET /astreintes HTTP/1.1" 200 -
 * Serving Flask app 'base' (lazy loading)
 * Environment: production
   WARNING: This is a development server. Do not use it in a production deployment.
   Use a production WSGI server instead.
 * Debug mode: on
Traceback (most recent call last):
  File "/Users/user/Documents/python/AstreinteFinale/base.py", line 417, in <module>
    app.run(debug=True, host="127.0.0.1",port=5000)
  File "/Users/user/Documents/python/AstreinteFinale/venv/lib/python3.10/site-packages/flask/app.py", line 920, in run
    run_simple(t.cast(str, host), port, self, **options)
  File "/Users/user/Documents/python/AstreinteFinale/venv/lib/python3.10/site-packages/werkzeug/serving.py", line 984, in run_simple
    s.bind(server_address)
OSError: [Errno 48] Address already in use
 * Serving Flask app 'base' (lazy loading)
 * Environment: production
   WARNING: This is a development server. Do not use it in a production deployment.
   Use a production WSGI server instead.
 * Debug mode: on
Traceback (most recent call last):
  File "/Users/user/Documents/python/AstreinteFinale/base.py", line 417, in <module>
    app.run(debug=True, host="127.0.0.1",port=5000)
  File "/Users/user/Documents/python/AstreinteFinale/venv/lib/python3.10/site-packages/flask/app.py", line 920, in run
    run_simple(t.cast(str, host), port, self, **options)
  File "/Users/user/Documents/python/AstreinteFinale/venv/lib/python3.10/site-packages/werkzeug/serving.py", line 984, in run_simple
    s.bind(server_address)
OSError: [Errno 48] Address already in use
127.0.0.1 - - [03/Jan/2022 10:28:12] "GET /astreintes HTTP/1.1" 200 -
 * Serving Flask app 'base' (lazy loading)
 * Environment: production
   WARNING: This is a development server. Do not use it in a production deployment.
   Use a production WSGI server instead.
 * Debug mode: on
Traceback (most recent call last):
  File "/Users/user/Documents/python/AstreinteFinale/base.py", line 417, in <module>
    app.run(debug=True, host="127.0.0.1",port=5000)
  File "/Users/user/Documents/python/AstreinteFinale/venv/lib/python3.10/site-packages/flask/app.py", line 920, in run
    run_simple(t.cast(str, host), port, self, **options)
  File "/Users/user/Documents/python/AstreinteFinale/venv/lib/python3.10/site-packages/werkzeug/serving.py", line 984, in run_simple
    s.bind(server_address)
OSError: [Errno 48] Address already in use
 * Serving Flask app 'base' (lazy loading)
 * Environment: production
   WARNING: This is a development server. Do not use it in a production deployment.
   Use a production WSGI server instead.
 * Debug mode: on
Traceback (most recent call last):
  File "/Users/user/Documents/python/AstreinteFinale/base.py", line 417, in <module>
    app.run(debug=True, host="127.0.0.1",port=5000)
  File "/Users/user/Documents/python/AstreinteFinale/venv/lib/python3.10/site-packages/flask/app.py", line 920, in run
    run_simple(t.cast(str, host), port, self, **options)
  File "/Users/user/Documents/python/AstreinteFinale/venv/lib/python3.10/site-packages/werkzeug/serving.py", line 984, in run_simple
    s.bind(server_address)
OSError: [Errno 48] Address already in use
127.0.0.1 - - [03/Jan/2022 10:30:10] "GET /astreintes HTTP/1.1" 200 -
 * Serving Flask app 'base' (lazy loading)
 * Environment: production
   WARNING: This is a development server. Do not use it in a production deployment.
   Use a production WSGI server instead.
 * Debug mode: on
Traceback (most recent call last):
  File "/Users/user/Documents/python/AstreinteFinale/base.py", line 417, in <module>
    app.run(debug=True, host="127.0.0.1",port=5000)
  File "/Users/user/Documents/python/AstreinteFinale/venv/lib/python3.10/site-packages/flask/app.py", line 920, in run
    run_simple(t.cast(str, host), port, self, **options)
  File "/Users/user/Documents/python/AstreinteFinale/venv/lib/python3.10/site-packages/werkzeug/serving.py", line 984, in run_simple
    s.bind(server_address)
OSError: [Errno 48] Address already in use
 * Serving Flask app 'base' (lazy loading)
 * Environment: production
   WARNING: This is a development server. Do not use it in a production deployment.
   Use a production WSGI server instead.
 * Debug mode: on
Traceback (most recent call last):
  File "/Users/user/Documents/python/AstreinteFinale/base.py", line 417, in <module>
    app.run(debug=True, host="127.0.0.1",port=5000)
  File "/Users/user/Documents/python/AstreinteFinale/venv/lib/python3.10/site-packages/flask/app.py", line 920, in run
    run_simple(t.cast(str, host), port, self, **options)
  File "/Users/user/Documents/python/AstreinteFinale/venv/lib/python3.10/site-packages/werkzeug/serving.py", line 984, in run_simple
    s.bind(server_address)
OSError: [Errno 48] Address already in use
127.0.0.1 - - [03/Jan/2022 10:32:12] "GET /astreintes HTTP/1.1" 200 -
 * Serving Flask app 'base' (lazy loading)
 * Environment: production
   WARNING: This is a development server. Do not use it in a production deployment.
   Use a production WSGI server instead.
 * Debug mode: on
Traceback (most recent call last):
  File "/Users/user/Documents/python/AstreinteFinale/base.py", line 417, in <module>
    app.run(debug=True, host="127.0.0.1",port=5000)
  File "/Users/user/Documents/python/AstreinteFinale/venv/lib/python3.10/site-packages/flask/app.py", line 920, in run
    run_simple(t.cast(str, host), port, self, **options)
  File "/Users/user/Documents/python/AstreinteFinale/venv/lib/python3.10/site-packages/werkzeug/serving.py", line 984, in run_simple
    s.bind(server_address)
OSError: [Errno 48] Address already in use
 * Serving Flask app 'base' (lazy loading)
 * Environment: production
   WARNING: This is a development server. Do not use it in a production deployment.
   Use a production WSGI server instead.
 * Debug mode: on
Traceback (most recent call last):
  File "/Users/user/Documents/python/AstreinteFinale/base.py", line 417, in <module>
    app.run(debug=True, host="127.0.0.1",port=5000)
  File "/Users/user/Documents/python/AstreinteFinale/venv/lib/python3.10/site-packages/flask/app.py", line 920, in run
    run_simple(t.cast(str, host), port, self, **options)
  File "/Users/user/Documents/python/AstreinteFinale/venv/lib/python3.10/site-packages/werkzeug/serving.py", line 984, in run_simple
    s.bind(server_address)
OSError: [Errno 48] Address already in use
127.0.0.1 - - [03/Jan/2022 10:34:09] "GET /astreintes HTTP/1.1" 200 -
 * Serving Flask app 'base' (lazy loading)
 * Environment: production
   WARNING: This is a development server. Do not use it in a production deployment.
   Use a production WSGI server instead.
 * Debug mode: on
Traceback (most recent call last):
  File "/Users/user/Documents/python/AstreinteFinale/base.py", line 417, in <module>
    app.run(debug=True, host="127.0.0.1",port=5000)
  File "/Users/user/Documents/python/AstreinteFinale/venv/lib/python3.10/site-packages/flask/app.py", line 920, in run
    run_simple(t.cast(str, host), port, self, **options)
  File "/Users/user/Documents/python/AstreinteFinale/venv/lib/python3.10/site-packages/werkzeug/serving.py", line 984, in run_simple
    s.bind(server_address)
OSError: [Errno 48] Address already in use
 * Serving Flask app 'base' (lazy loading)
 * Environment: production
   WARNING: This is a development server. Do not use it in a production deployment.
   Use a production WSGI server instead.
 * Debug mode: on
Traceback (most recent call last):
  File "/Users/user/Documents/python/AstreinteFinale/base.py", line 417, in <module>
    app.run(debug=True, host="127.0.0.1",port=5000)
  File "/Users/user/Documents/python/AstreinteFinale/venv/lib/python3.10/site-packages/flask/app.py", line 920, in run
    run_simple(t.cast(str, host), port, self, **options)
  File "/Users/user/Documents/python/AstreinteFinale/venv/lib/python3.10/site-packages/werkzeug/serving.py", line 984, in run_simple
    s.bind(server_address)
OSError: [Errno 48] Address already in use
127.0.0.1 - - [03/Jan/2022 10:36:10] "GET /astreintes HTTP/1.1" 200 -
 * Serving Flask app 'base' (lazy loading)
 * Environment: production
   WARNING: This is a development server. Do not use it in a production deployment.
   Use a production WSGI server instead.
 * Debug mode: on
Traceback (most recent call last):
  File "/Users/user/Documents/python/AstreinteFinale/base.py", line 417, in <module>
    app.run(debug=True, host="127.0.0.1",port=5000)
  File "/Users/user/Documents/python/AstreinteFinale/venv/lib/python3.10/site-packages/flask/app.py", line 920, in run
    run_simple(t.cast(str, host), port, self, **options)
  File "/Users/user/Documents/python/AstreinteFinale/venv/lib/python3.10/site-packages/werkzeug/serving.py", line 984, in run_simple
    s.bind(server_address)
OSError: [Errno 48] Address already in use
 * Serving Flask app 'base' (lazy loading)
 * Environment: production
   WARNING: This is a development server. Do not use it in a production deployment.
   Use a production WSGI server instead.
 * Debug mode: on
Traceback (most recent call last):
  File "/Users/user/Documents/python/AstreinteFinale/base.py", line 417, in <module>
    app.run(debug=True, host="127.0.0.1",port=5000)
  File "/Users/user/Documents/python/AstreinteFinale/venv/lib/python3.10/site-packages/flask/app.py", line 920, in run
    run_simple(t.cast(str, host), port, self, **options)
  File "/Users/user/Documents/python/AstreinteFinale/venv/lib/python3.10/site-packages/werkzeug/serving.py", line 984, in run_simple
    s.bind(server_address)
OSError: [Errno 48] Address already in use
127.0.0.1 - - [03/Jan/2022 10:38:17] "GET /astreintes HTTP/1.1" 200 -
 * Serving Flask app 'base' (lazy loading)
 * Environment: production
   WARNING: This is a development server. Do not use it in a production deployment.
   Use a production WSGI server instead.
 * Debug mode: on
Traceback (most recent call last):
  File "/Users/user/Documents/python/AstreinteFinale/base.py", line 417, in <module>
    app.run(debug=True, host="127.0.0.1",port=5000)
  File "/Users/user/Documents/python/AstreinteFinale/venv/lib/python3.10/site-packages/flask/app.py", line 920, in run
    run_simple(t.cast(str, host), port, self, **options)
  File "/Users/user/Documents/python/AstreinteFinale/venv/lib/python3.10/site-packages/werkzeug/serving.py", line 984, in run_simple
    s.bind(server_address)
OSError: [Errno 48] Address already in use
 * Serving Flask app 'base' (lazy loading)
 * Environment: production
   WARNING: This is a development server. Do not use it in a production deployment.
   Use a production WSGI server instead.
 * Debug mode: on
Traceback (most recent call last):
  File "/Users/user/Documents/python/AstreinteFinale/base.py", line 417, in <module>
    app.run(debug=True, host="127.0.0.1",port=5000)
  File "/Users/user/Documents/python/AstreinteFinale/venv/lib/python3.10/site-packages/flask/app.py", line 920, in run
    run_simple(t.cast(str, host), port, self, **options)
  File "/Users/user/Documents/python/AstreinteFinale/venv/lib/python3.10/site-packages/werkzeug/serving.py", line 984, in run_simple
    s.bind(server_address)
OSError: [Errno 48] Address already in use
127.0.0.1 - - [03/Jan/2022 10:40:10] "GET /astreintes HTTP/1.1" 200 -
 * Serving Flask app 'base' (lazy loading)
 * Environment: production
   WARNING: This is a development server. Do not use it in a production deployment.
   Use a production WSGI server instead.
 * Debug mode: on
Traceback (most recent call last):
  File "/Users/user/Documents/python/AstreinteFinale/base.py", line 417, in <module>
    app.run(debug=True, host="127.0.0.1",port=5000)
  File "/Users/user/Documents/python/AstreinteFinale/venv/lib/python3.10/site-packages/flask/app.py", line 920, in run
    run_simple(t.cast(str, host), port, self, **options)
  File "/Users/user/Documents/python/AstreinteFinale/venv/lib/python3.10/site-packages/werkzeug/serving.py", line 984, in run_simple
    s.bind(server_address)
OSError: [Errno 48] Address already in use
 * Serving Flask app 'base' (lazy loading)
 * Environment: production
   WARNING: This is a development server. Do not use it in a production deployment.
   Use a production WSGI server instead.
 * Debug mode: on
Traceback (most recent call last):
  File "/Users/user/Documents/python/AstreinteFinale/base.py", line 417, in <module>
    app.run(debug=True, host="127.0.0.1",port=5000)
  File "/Users/user/Documents/python/AstreinteFinale/venv/lib/python3.10/site-packages/flask/app.py", line 920, in run
    run_simple(t.cast(str, host), port, self, **options)
  File "/Users/user/Documents/python/AstreinteFinale/venv/lib/python3.10/site-packages/werkzeug/serving.py", line 984, in run_simple
    s.bind(server_address)
OSError: [Errno 48] Address already in use
127.0.0.1 - - [03/Jan/2022 10:42:08] "GET /astreintes HTTP/1.1" 200 -
 * Serving Flask app 'base' (lazy loading)
 * Environment: production
   WARNING: This is a development server. Do not use it in a production deployment.
   Use a production WSGI server instead.
 * Debug mode: on
Traceback (most recent call last):
  File "/Users/user/Documents/python/AstreinteFinale/base.py", line 417, in <module>
    app.run(debug=True, host="127.0.0.1",port=5000)
  File "/Users/user/Documents/python/AstreinteFinale/venv/lib/python3.10/site-packages/flask/app.py", line 920, in run
    run_simple(t.cast(str, host), port, self, **options)
  File "/Users/user/Documents/python/AstreinteFinale/venv/lib/python3.10/site-packages/werkzeug/serving.py", line 984, in run_simple
    s.bind(server_address)
OSError: [Errno 48] Address already in use
 * Serving Flask app 'base' (lazy loading)
 * Environment: production
   WARNING: This is a development server. Do not use it in a production deployment.
   Use a production WSGI server instead.
 * Debug mode: on
Traceback (most recent call last):
  File "/Users/user/Documents/python/AstreinteFinale/base.py", line 417, in <module>
    app.run(debug=True, host="127.0.0.1",port=5000)
  File "/Users/user/Documents/python/AstreinteFinale/venv/lib/python3.10/site-packages/flask/app.py", line 920, in run
    run_simple(t.cast(str, host), port, self, **options)
  File "/Users/user/Documents/python/AstreinteFinale/venv/lib/python3.10/site-packages/werkzeug/serving.py", line 984, in run_simple
    s.bind(server_address)
OSError: [Errno 48] Address already in use
127.0.0.1 - - [03/Jan/2022 10:44:10] "GET /astreintes HTTP/1.1" 200 -
 * Serving Flask app 'base' (lazy loading)
 * Environment: production
   WARNING: This is a development server. Do not use it in a production deployment.
   Use a production WSGI server instead.
 * Debug mode: on
Traceback (most recent call last):
  File "/Users/user/Documents/python/AstreinteFinale/base.py", line 417, in <module>
    app.run(debug=True, host="127.0.0.1",port=5000)
  File "/Users/user/Documents/python/AstreinteFinale/venv/lib/python3.10/site-packages/flask/app.py", line 920, in run
    run_simple(t.cast(str, host), port, self, **options)
  File "/Users/user/Documents/python/AstreinteFinale/venv/lib/python3.10/site-packages/werkzeug/serving.py", line 984, in run_simple
    s.bind(server_address)
OSError: [Errno 48] Address already in use
 * Serving Flask app 'base' (lazy loading)
 * Environment: production
   WARNING: This is a development server. Do not use it in a production deployment.
   Use a production WSGI server instead.
 * Debug mode: on
Traceback (most recent call last):
  File "/Users/user/Documents/python/AstreinteFinale/base.py", line 417, in <module>
    app.run(debug=True, host="127.0.0.1",port=5000)
  File "/Users/user/Documents/python/AstreinteFinale/venv/lib/python3.10/site-packages/flask/app.py", line 920, in run
    run_simple(t.cast(str, host), port, self, **options)
  File "/Users/user/Documents/python/AstreinteFinale/venv/lib/python3.10/site-packages/werkzeug/serving.py", line 984, in run_simple
    s.bind(server_address)
OSError: [Errno 48] Address already in use
127.0.0.1 - - [03/Jan/2022 10:46:13] "GET /astreintes HTTP/1.1" 200 -
 * Serving Flask app 'base' (lazy loading)
 * Environment: production
   WARNING: This is a development server. Do not use it in a production deployment.
   Use a production WSGI server instead.
 * Debug mode: on
Traceback (most recent call last):
  File "/Users/user/Documents/python/AstreinteFinale/base.py", line 417, in <module>
    app.run(debug=True, host="127.0.0.1",port=5000)
  File "/Users/user/Documents/python/AstreinteFinale/venv/lib/python3.10/site-packages/flask/app.py", line 920, in run
    run_simple(t.cast(str, host), port, self, **options)
  File "/Users/user/Documents/python/AstreinteFinale/venv/lib/python3.10/site-packages/werkzeug/serving.py", line 984, in run_simple
    s.bind(server_address)
OSError: [Errno 48] Address already in use
 * Serving Flask app 'base' (lazy loading)
 * Environment: production
   WARNING: This is a development server. Do not use it in a production deployment.
   Use a production WSGI server instead.
 * Debug mode: on
Traceback (most recent call last):
  File "/Users/user/Documents/python/AstreinteFinale/base.py", line 417, in <module>
    app.run(debug=True, host="127.0.0.1",port=5000)
  File "/Users/user/Documents/python/AstreinteFinale/venv/lib/python3.10/site-packages/flask/app.py", line 920, in run
    run_simple(t.cast(str, host), port, self, **options)
  File "/Users/user/Documents/python/AstreinteFinale/venv/lib/python3.10/site-packages/werkzeug/serving.py", line 984, in run_simple
    s.bind(server_address)
OSError: [Errno 48] Address already in use
127.0.0.1 - - [03/Jan/2022 10:48:19] "GET /astreintes HTTP/1.1" 200 -
 * Serving Flask app 'base' (lazy loading)
 * Environment: production
   WARNING: This is a development server. Do not use it in a production deployment.
   Use a production WSGI server instead.
 * Debug mode: on
Traceback (most recent call last):
  File "/Users/user/Documents/python/AstreinteFinale/base.py", line 417, in <module>
    app.run(debug=True, host="127.0.0.1",port=5000)
  File "/Users/user/Documents/python/AstreinteFinale/venv/lib/python3.10/site-packages/flask/app.py", line 920, in run
    run_simple(t.cast(str, host), port, self, **options)
  File "/Users/user/Documents/python/AstreinteFinale/venv/lib/python3.10/site-packages/werkzeug/serving.py", line 984, in run_simple
    s.bind(server_address)
OSError: [Errno 48] Address already in use
 * Serving Flask app 'base' (lazy loading)
 * Environment: production
   WARNING: This is a development server. Do not use it in a production deployment.
   Use a production WSGI server instead.
 * Debug mode: on
Traceback (most recent call last):
  File "/Users/user/Documents/python/AstreinteFinale/base.py", line 417, in <module>
    app.run(debug=True, host="127.0.0.1",port=5000)
  File "/Users/user/Documents/python/AstreinteFinale/venv/lib/python3.10/site-packages/flask/app.py", line 920, in run
    run_simple(t.cast(str, host), port, self, **options)
  File "/Users/user/Documents/python/AstreinteFinale/venv/lib/python3.10/site-packages/werkzeug/serving.py", line 984, in run_simple
    s.bind(server_address)
OSError: [Errno 48] Address already in use
127.0.0.1 - - [03/Jan/2022 10:50:10] "GET /astreintes HTTP/1.1" 200 -
 * Serving Flask app 'base' (lazy loading)
 * Environment: production
   WARNING: This is a development server. Do not use it in a production deployment.
   Use a production WSGI server instead.
 * Debug mode: on
Traceback (most recent call last):
  File "/Users/user/Documents/python/AstreinteFinale/base.py", line 417, in <module>
    app.run(debug=True, host="127.0.0.1",port=5000)
  File "/Users/user/Documents/python/AstreinteFinale/venv/lib/python3.10/site-packages/flask/app.py", line 920, in run
    run_simple(t.cast(str, host), port, self, **options)
  File "/Users/user/Documents/python/AstreinteFinale/venv/lib/python3.10/site-packages/werkzeug/serving.py", line 984, in run_simple
    s.bind(server_address)
OSError: [Errno 48] Address already in use
127.0.0.1 - - [03/Jan/2022 10:53:05] "GET /astreintes HTTP/1.1" 200 -
 * Serving Flask app 'base' (lazy loading)
 * Serving Flask app 'base' (lazy loading)
 * Environment: production
   WARNING: This is a development server. Do not use it in a production deployment.
   Use a production WSGI server instead.
 * Debug mode: on
 * Environment: production
   WARNING: This is a development server. Do not use it in a production deployment.
   Use a production WSGI server instead.
 * Debug mode: on
Traceback (most recent call last):
  File "/Users/user/Documents/python/AstreinteFinale/base.py", line 417, in <module>
Traceback (most recent call last):
  File "/Users/user/Documents/python/AstreinteFinale/base.py", line 417, in <module>
    app.run(debug=True, host="127.0.0.1",port=5000)
  File "/Users/user/Documents/python/AstreinteFinale/venv/lib/python3.10/site-packages/flask/app.py", line 920, in run
    app.run(debug=True, host="127.0.0.1",port=5000)
  File "/Users/user/Documents/python/AstreinteFinale/venv/lib/python3.10/site-packages/flask/app.py", line 920, in run
    run_simple(t.cast(str, host), port, self, **options)
    run_simple(t.cast(str, host), port, self, **options)
  File "/Users/user/Documents/python/AstreinteFinale/venv/lib/python3.10/site-packages/werkzeug/serving.py", line 984, in run_simple
  File "/Users/user/Documents/python/AstreinteFinale/venv/lib/python3.10/site-packages/werkzeug/serving.py", line 984, in run_simple
    s.bind(server_address)
    s.bind(server_address)
OSError: [Errno 48] Address already in use
OSError: [Errno 48] Address already in use
127.0.0.1 - - [03/Jan/2022 10:54:19] "GET /astreintes HTTP/1.1" 200 -
 * Serving Flask app 'base' (lazy loading)
 * Environment: production
   WARNING: This is a development server. Do not use it in a production deployment.
   Use a production WSGI server instead.
 * Debug mode: on
Traceback (most recent call last):
  File "/Users/user/Documents/python/AstreinteFinale/base.py", line 417, in <module>
    app.run(debug=True, host="127.0.0.1",port=5000)
  File "/Users/user/Documents/python/AstreinteFinale/venv/lib/python3.10/site-packages/flask/app.py", line 920, in run
    run_simple(t.cast(str, host), port, self, **options)
  File "/Users/user/Documents/python/AstreinteFinale/venv/lib/python3.10/site-packages/werkzeug/serving.py", line 984, in run_simple
    s.bind(server_address)
OSError: [Errno 48] Address already in use
 * Serving Flask app 'base' (lazy loading)
 * Environment: production
   WARNING: This is a development server. Do not use it in a production deployment.
   Use a production WSGI server instead.
 * Debug mode: on
Traceback (most recent call last):
  File "/Users/user/Documents/python/AstreinteFinale/base.py", line 417, in <module>
    app.run(debug=True, host="127.0.0.1",port=5000)
  File "/Users/user/Documents/python/AstreinteFinale/venv/lib/python3.10/site-packages/flask/app.py", line 920, in run
    run_simple(t.cast(str, host), port, self, **options)
  File "/Users/user/Documents/python/AstreinteFinale/venv/lib/python3.10/site-packages/werkzeug/serving.py", line 984, in run_simple
    s.bind(server_address)
OSError: [Errno 48] Address already in use
127.0.0.1 - - [03/Jan/2022 10:56:16] "GET /astreintes HTTP/1.1" 200 -
 * Serving Flask app 'base' (lazy loading)
 * Environment: production
   WARNING: This is a development server. Do not use it in a production deployment.
   Use a production WSGI server instead.
 * Debug mode: on
Traceback (most recent call last):
  File "/Users/user/Documents/python/AstreinteFinale/base.py", line 417, in <module>
    app.run(debug=True, host="127.0.0.1",port=5000)
  File "/Users/user/Documents/python/AstreinteFinale/venv/lib/python3.10/site-packages/flask/app.py", line 920, in run
    run_simple(t.cast(str, host), port, self, **options)
  File "/Users/user/Documents/python/AstreinteFinale/venv/lib/python3.10/site-packages/werkzeug/serving.py", line 984, in run_simple
    s.bind(server_address)
OSError: [Errno 48] Address already in use
 * Serving Flask app 'base' (lazy loading)
 * Environment: production
   WARNING: This is a development server. Do not use it in a production deployment.
   Use a production WSGI server instead.
 * Debug mode: on
Traceback (most recent call last):
  File "/Users/user/Documents/python/AstreinteFinale/base.py", line 417, in <module>
    app.run(debug=True, host="127.0.0.1",port=5000)
  File "/Users/user/Documents/python/AstreinteFinale/venv/lib/python3.10/site-packages/flask/app.py", line 920, in run
    run_simple(t.cast(str, host), port, self, **options)
  File "/Users/user/Documents/python/AstreinteFinale/venv/lib/python3.10/site-packages/werkzeug/serving.py", line 984, in run_simple
    s.bind(server_address)
OSError: [Errno 48] Address already in use
 * Serving Flask app 'base' (lazy loading)
 * Environment: production
   WARNING: This is a development server. Do not use it in a production deployment.
   Use a production WSGI server instead.
 * Debug mode: on
Traceback (most recent call last):
  File "/Users/user/Documents/python/AstreinteFinale/base.py", line 417, in <module>
    app.run(debug=True, host="127.0.0.1",port=5000)
  File "/Users/user/Documents/python/AstreinteFinale/venv/lib/python3.10/site-packages/flask/app.py", line 920, in run
    run_simple(t.cast(str, host), port, self, **options)
  File "/Users/user/Documents/python/AstreinteFinale/venv/lib/python3.10/site-packages/werkzeug/serving.py", line 984, in run_simple
    s.bind(server_address)
OSError: [Errno 48] Address already in use
127.0.0.1 - - [03/Jan/2022 10:59:27] "GET /astreintes HTTP/1.1" 200 -
 * Serving Flask app 'base' (lazy loading)
 * Serving Flask app 'base' (lazy loading)
 * Environment: production
 * Environment: production
   WARNING: This is a development server. Do not use it in a production deployment.
   WARNING: This is a development server. Do not use it in a production deployment.
   Use a production WSGI server instead.
   Use a production WSGI server instead.
 * Debug mode: on
 * Debug mode: on
Traceback (most recent call last):
  File "/Users/user/Documents/python/AstreinteFinale/base.py", line 417, in <module>
Traceback (most recent call last):
  File "/Users/user/Documents/python/AstreinteFinale/base.py", line 417, in <module>
    app.run(debug=True, host="127.0.0.1",port=5000)
    app.run(debug=True, host="127.0.0.1",port=5000)
  File "/Users/user/Documents/python/AstreinteFinale/venv/lib/python3.10/site-packages/flask/app.py", line 920, in run
  File "/Users/user/Documents/python/AstreinteFinale/venv/lib/python3.10/site-packages/flask/app.py", line 920, in run
    run_simple(t.cast(str, host), port, self, **options)
    run_simple(t.cast(str, host), port, self, **options)
  File "/Users/user/Documents/python/AstreinteFinale/venv/lib/python3.10/site-packages/werkzeug/serving.py", line 984, in run_simple
  File "/Users/user/Documents/python/AstreinteFinale/venv/lib/python3.10/site-packages/werkzeug/serving.py", line 984, in run_simple
    s.bind(server_address)
    s.bind(server_address)
OSError: [Errno 48] Address already in use
OSError: [Errno 48] Address already in use
127.0.0.1 - - [03/Jan/2022 11:01:39] "GET /astreintes HTTP/1.1" 200 -
127.0.0.1 - - [03/Jan/2022 11:02:26] "GET /astreintes HTTP/1.1" 200 -
 * Serving Flask app 'base' (lazy loading)
 * Environment: production
   WARNING: This is a development server. Do not use it in a production deployment.
   Use a production WSGI server instead.
 * Debug mode: on
Traceback (most recent call last):
  File "/Users/user/Documents/python/AstreinteFinale/base.py", line 417, in <module>
    app.run(debug=True, host="127.0.0.1",port=5000)
  File "/Users/user/Documents/python/AstreinteFinale/venv/lib/python3.10/site-packages/flask/app.py", line 920, in run
    run_simple(t.cast(str, host), port, self, **options)
  File "/Users/user/Documents/python/AstreinteFinale/venv/lib/python3.10/site-packages/werkzeug/serving.py", line 984, in run_simple
    s.bind(server_address)
OSError: [Errno 48] Address already in use
 * Serving Flask app 'base' (lazy loading)
 * Environment: production
   WARNING: This is a development server. Do not use it in a production deployment.
   Use a production WSGI server instead.
 * Debug mode: on
Traceback (most recent call last):
  File "/Users/user/Documents/python/AstreinteFinale/base.py", line 417, in <module>
    app.run(debug=True, host="127.0.0.1",port=5000)
  File "/Users/user/Documents/python/AstreinteFinale/venv/lib/python3.10/site-packages/flask/app.py", line 920, in run
    run_simple(t.cast(str, host), port, self, **options)
  File "/Users/user/Documents/python/AstreinteFinale/venv/lib/python3.10/site-packages/werkzeug/serving.py", line 984, in run_simple
    s.bind(server_address)
OSError: [Errno 48] Address already in use
 * Serving Flask app 'base' (lazy loading)
 * Environment: production
   WARNING: This is a development server. Do not use it in a production deployment.
   Use a production WSGI server instead.
 * Debug mode: on
Traceback (most recent call last):
  File "/Users/user/Documents/python/AstreinteFinale/base.py", line 417, in <module>
    app.run(debug=True, host="127.0.0.1",port=5000)
  File "/Users/user/Documents/python/AstreinteFinale/venv/lib/python3.10/site-packages/flask/app.py", line 920, in run
    run_simple(t.cast(str, host), port, self, **options)
  File "/Users/user/Documents/python/AstreinteFinale/venv/lib/python3.10/site-packages/werkzeug/serving.py", line 984, in run_simple
    s.bind(server_address)
OSError: [Errno 48] Address already in use
 * Serving Flask app 'base' (lazy loading)
 * Environment: production
   WARNING: This is a development server. Do not use it in a production deployment.
   Use a production WSGI server instead.
 * Debug mode: on
Traceback (most recent call last):
  File "/Users/user/Documents/python/AstreinteFinale/base.py", line 417, in <module>
    app.run(debug=True, host="127.0.0.1",port=5000)
  File "/Users/user/Documents/python/AstreinteFinale/venv/lib/python3.10/site-packages/flask/app.py", line 920, in run
    run_simple(t.cast(str, host), port, self, **options)
  File "/Users/user/Documents/python/AstreinteFinale/venv/lib/python3.10/site-packages/werkzeug/serving.py", line 984, in run_simple
    s.bind(server_address)
OSError: [Errno 48] Address already in use
127.0.0.1 - - [03/Jan/2022 11:04:16] "GET /astreintes HTTP/1.1" 200 -
 * Serving Flask app 'base' (lazy loading)
 * Environment: production
   WARNING: This is a development server. Do not use it in a production deployment.
   Use a production WSGI server instead.
 * Debug mode: on
Traceback (most recent call last):
  File "/Users/user/Documents/python/AstreinteFinale/base.py", line 417, in <module>
    app.run(debug=True, host="127.0.0.1",port=5000)
  File "/Users/user/Documents/python/AstreinteFinale/venv/lib/python3.10/site-packages/flask/app.py", line 920, in run
    run_simple(t.cast(str, host), port, self, **options)
  File "/Users/user/Documents/python/AstreinteFinale/venv/lib/python3.10/site-packages/werkzeug/serving.py", line 984, in run_simple
    s.bind(server_address)
OSError: [Errno 48] Address already in use
127.0.0.1 - - [03/Jan/2022 11:07:47] "GET /astreintes HTTP/1.1" 200 -
 * Serving Flask app 'base' (lazy loading)
 * Serving Flask app 'base' (lazy loading)
 * Serving Flask app 'base' (lazy loading)
 * Environment: production
 * Environment: production
 * Environment: production
   WARNING: This is a development server. Do not use it in a production deployment.
   WARNING: This is a development server. Do not use it in a production deployment.
   WARNING: This is a development server. Do not use it in a production deployment.
   Use a production WSGI server instead.
   Use a production WSGI server instead.
   Use a production WSGI server instead.
 * Debug mode: on
 * Debug mode: on
 * Debug mode: on
Traceback (most recent call last):
  File "/Users/user/Documents/python/AstreinteFinale/base.py", line 417, in <module>
Traceback (most recent call last):
  File "/Users/user/Documents/python/AstreinteFinale/base.py", line 417, in <module>
Traceback (most recent call last):
  File "/Users/user/Documents/python/AstreinteFinale/base.py", line 417, in <module>
    app.run(debug=True, host="127.0.0.1",port=5000)
  File "/Users/user/Documents/python/AstreinteFinale/venv/lib/python3.10/site-packages/flask/app.py", line 920, in run
    app.run(debug=True, host="127.0.0.1",port=5000)
  File "/Users/user/Documents/python/AstreinteFinale/venv/lib/python3.10/site-packages/flask/app.py", line 920, in run
    app.run(debug=True, host="127.0.0.1",port=5000)
  File "/Users/user/Documents/python/AstreinteFinale/venv/lib/python3.10/site-packages/flask/app.py", line 920, in run
    run_simple(t.cast(str, host), port, self, **options)
    run_simple(t.cast(str, host), port, self, **options)
  File "/Users/user/Documents/python/AstreinteFinale/venv/lib/python3.10/site-packages/werkzeug/serving.py", line 984, in run_simple
  File "/Users/user/Documents/python/AstreinteFinale/venv/lib/python3.10/site-packages/werkzeug/serving.py", line 984, in run_simple
    run_simple(t.cast(str, host), port, self, **options)
  File "/Users/user/Documents/python/AstreinteFinale/venv/lib/python3.10/site-packages/werkzeug/serving.py", line 984, in run_simple
    s.bind(server_address)
OSError: [Errno 48] Address already in use
    s.bind(server_address)
OSError: [Errno 48] Address already in use
    s.bind(server_address)
OSError: [Errno 48] Address already in use
 * Serving Flask app 'base' (lazy loading)
 * Environment: production
   WARNING: This is a development server. Do not use it in a production deployment.
   Use a production WSGI server instead.
 * Debug mode: on
Traceback (most recent call last):
  File "/Users/user/Documents/python/AstreinteFinale/base.py", line 417, in <module>
    app.run(debug=True, host="127.0.0.1",port=5000)
  File "/Users/user/Documents/python/AstreinteFinale/venv/lib/python3.10/site-packages/flask/app.py", line 920, in run
    run_simple(t.cast(str, host), port, self, **options)
  File "/Users/user/Documents/python/AstreinteFinale/venv/lib/python3.10/site-packages/werkzeug/serving.py", line 984, in run_simple
    s.bind(server_address)
OSError: [Errno 48] Address already in use
127.0.0.1 - - [03/Jan/2022 11:08:12] "GET /astreintes HTTP/1.1" 200 -
 * Serving Flask app 'base' (lazy loading)
 * Environment: production
   WARNING: This is a development server. Do not use it in a production deployment.
   Use a production WSGI server instead.
 * Debug mode: on
Traceback (most recent call last):
  File "/Users/user/Documents/python/AstreinteFinale/base.py", line 417, in <module>
    app.run(debug=True, host="127.0.0.1",port=5000)
  File "/Users/user/Documents/python/AstreinteFinale/venv/lib/python3.10/site-packages/flask/app.py", line 920, in run
    run_simple(t.cast(str, host), port, self, **options)
  File "/Users/user/Documents/python/AstreinteFinale/venv/lib/python3.10/site-packages/werkzeug/serving.py", line 984, in run_simple
    s.bind(server_address)
OSError: [Errno 48] Address already in use
127.0.0.1 - - [03/Jan/2022 11:10:12] "GET /astreintes HTTP/1.1" 200 -
 * Serving Flask app 'base' (lazy loading)
 * Environment: production
   WARNING: This is a development server. Do not use it in a production deployment.
   Use a production WSGI server instead.
 * Debug mode: on
Traceback (most recent call last):
  File "/Users/user/Documents/python/AstreinteFinale/base.py", line 417, in <module>
    app.run(debug=True, host="127.0.0.1",port=5000)
  File "/Users/user/Documents/python/AstreinteFinale/venv/lib/python3.10/site-packages/flask/app.py", line 920, in run
    run_simple(t.cast(str, host), port, self, **options)
  File "/Users/user/Documents/python/AstreinteFinale/venv/lib/python3.10/site-packages/werkzeug/serving.py", line 984, in run_simple
    s.bind(server_address)
OSError: [Errno 48] Address already in use
 * Serving Flask app 'base' (lazy loading)
 * Environment: production
   WARNING: This is a development server. Do not use it in a production deployment.
   Use a production WSGI server instead.
 * Debug mode: on
Traceback (most recent call last):
  File "/Users/user/Documents/python/AstreinteFinale/base.py", line 417, in <module>
    app.run(debug=True, host="127.0.0.1",port=5000)
  File "/Users/user/Documents/python/AstreinteFinale/venv/lib/python3.10/site-packages/flask/app.py", line 920, in run
    run_simple(t.cast(str, host), port, self, **options)
  File "/Users/user/Documents/python/AstreinteFinale/venv/lib/python3.10/site-packages/werkzeug/serving.py", line 984, in run_simple
    s.bind(server_address)
OSError: [Errno 48] Address already in use
127.0.0.1 - - [03/Jan/2022 11:12:11] "GET /astreintes HTTP/1.1" 200 -
 * Serving Flask app 'base' (lazy loading)
 * Environment: production
   WARNING: This is a development server. Do not use it in a production deployment.
   Use a production WSGI server instead.
 * Debug mode: on
Traceback (most recent call last):
  File "/Users/user/Documents/python/AstreinteFinale/base.py", line 417, in <module>
    app.run(debug=True, host="127.0.0.1",port=5000)
  File "/Users/user/Documents/python/AstreinteFinale/venv/lib/python3.10/site-packages/flask/app.py", line 920, in run
    run_simple(t.cast(str, host), port, self, **options)
  File "/Users/user/Documents/python/AstreinteFinale/venv/lib/python3.10/site-packages/werkzeug/serving.py", line 984, in run_simple
    s.bind(server_address)
OSError: [Errno 48] Address already in use
 * Serving Flask app 'base' (lazy loading)
 * Environment: production
   WARNING: This is a development server. Do not use it in a production deployment.
   Use a production WSGI server instead.
 * Debug mode: on
Traceback (most recent call last):
  File "/Users/user/Documents/python/AstreinteFinale/base.py", line 417, in <module>
    app.run(debug=True, host="127.0.0.1",port=5000)
  File "/Users/user/Documents/python/AstreinteFinale/venv/lib/python3.10/site-packages/flask/app.py", line 920, in run
    run_simple(t.cast(str, host), port, self, **options)
  File "/Users/user/Documents/python/AstreinteFinale/venv/lib/python3.10/site-packages/werkzeug/serving.py", line 984, in run_simple
    s.bind(server_address)
OSError: [Errno 48] Address already in use
127.0.0.1 - - [03/Jan/2022 11:14:09] "GET /astreintes HTTP/1.1" 200 -
 * Serving Flask app 'base' (lazy loading)
 * Environment: production
   WARNING: This is a development server. Do not use it in a production deployment.
   Use a production WSGI server instead.
 * Debug mode: on
Traceback (most recent call last):
  File "/Users/user/Documents/python/AstreinteFinale/base.py", line 417, in <module>
    app.run(debug=True, host="127.0.0.1",port=5000)
  File "/Users/user/Documents/python/AstreinteFinale/venv/lib/python3.10/site-packages/flask/app.py", line 920, in run
    run_simple(t.cast(str, host), port, self, **options)
  File "/Users/user/Documents/python/AstreinteFinale/venv/lib/python3.10/site-packages/werkzeug/serving.py", line 984, in run_simple
    s.bind(server_address)
OSError: [Errno 48] Address already in use
 * Serving Flask app 'base' (lazy loading)
 * Environment: production
   WARNING: This is a development server. Do not use it in a production deployment.
   Use a production WSGI server instead.
 * Debug mode: on
Traceback (most recent call last):
  File "/Users/user/Documents/python/AstreinteFinale/base.py", line 417, in <module>
    app.run(debug=True, host="127.0.0.1",port=5000)
  File "/Users/user/Documents/python/AstreinteFinale/venv/lib/python3.10/site-packages/flask/app.py", line 920, in run
    run_simple(t.cast(str, host), port, self, **options)
  File "/Users/user/Documents/python/AstreinteFinale/venv/lib/python3.10/site-packages/werkzeug/serving.py", line 984, in run_simple
    s.bind(server_address)
OSError: [Errno 48] Address already in use
127.0.0.1 - - [03/Jan/2022 11:16:09] "GET /astreintes HTTP/1.1" 200 -
 * Serving Flask app 'base' (lazy loading)
 * Environment: production
   WARNING: This is a development server. Do not use it in a production deployment.
   Use a production WSGI server instead.
 * Debug mode: on
Traceback (most recent call last):
  File "/Users/user/Documents/python/AstreinteFinale/base.py", line 417, in <module>
    app.run(debug=True, host="127.0.0.1",port=5000)
  File "/Users/user/Documents/python/AstreinteFinale/venv/lib/python3.10/site-packages/flask/app.py", line 920, in run
    run_simple(t.cast(str, host), port, self, **options)
  File "/Users/user/Documents/python/AstreinteFinale/venv/lib/python3.10/site-packages/werkzeug/serving.py", line 984, in run_simple
    s.bind(server_address)
OSError: [Errno 48] Address already in use
 * Serving Flask app 'base' (lazy loading)
 * Environment: production
   WARNING: This is a development server. Do not use it in a production deployment.
   Use a production WSGI server instead.
 * Debug mode: on
Traceback (most recent call last):
  File "/Users/user/Documents/python/AstreinteFinale/base.py", line 417, in <module>
    app.run(debug=True, host="127.0.0.1",port=5000)
  File "/Users/user/Documents/python/AstreinteFinale/venv/lib/python3.10/site-packages/flask/app.py", line 920, in run
    run_simple(t.cast(str, host), port, self, **options)
  File "/Users/user/Documents/python/AstreinteFinale/venv/lib/python3.10/site-packages/werkzeug/serving.py", line 984, in run_simple
    s.bind(server_address)
OSError: [Errno 48] Address already in use
127.0.0.1 - - [03/Jan/2022 11:18:10] "GET /astreintes HTTP/1.1" 200 -
 * Serving Flask app 'base' (lazy loading)
 * Environment: production
   WARNING: This is a development server. Do not use it in a production deployment.
   Use a production WSGI server instead.
 * Debug mode: on
Traceback (most recent call last):
  File "/Users/user/Documents/python/AstreinteFinale/base.py", line 417, in <module>
    app.run(debug=True, host="127.0.0.1",port=5000)
  File "/Users/user/Documents/python/AstreinteFinale/venv/lib/python3.10/site-packages/flask/app.py", line 920, in run
    run_simple(t.cast(str, host), port, self, **options)
  File "/Users/user/Documents/python/AstreinteFinale/venv/lib/python3.10/site-packages/werkzeug/serving.py", line 984, in run_simple
    s.bind(server_address)
OSError: [Errno 48] Address already in use
 * Serving Flask app 'base' (lazy loading)
 * Environment: production
   WARNING: This is a development server. Do not use it in a production deployment.
   Use a production WSGI server instead.
 * Debug mode: on
Traceback (most recent call last):
  File "/Users/user/Documents/python/AstreinteFinale/base.py", line 417, in <module>
    app.run(debug=True, host="127.0.0.1",port=5000)
  File "/Users/user/Documents/python/AstreinteFinale/venv/lib/python3.10/site-packages/flask/app.py", line 920, in run
    run_simple(t.cast(str, host), port, self, **options)
  File "/Users/user/Documents/python/AstreinteFinale/venv/lib/python3.10/site-packages/werkzeug/serving.py", line 984, in run_simple
    s.bind(server_address)
OSError: [Errno 48] Address already in use
127.0.0.1 - - [03/Jan/2022 11:20:11] "GET /astreintes HTTP/1.1" 200 -
 * Serving Flask app 'base' (lazy loading)
 * Environment: production
   WARNING: This is a development server. Do not use it in a production deployment.
   Use a production WSGI server instead.
 * Debug mode: on
Traceback (most recent call last):
  File "/Users/user/Documents/python/AstreinteFinale/base.py", line 417, in <module>
    app.run(debug=True, host="127.0.0.1",port=5000)
  File "/Users/user/Documents/python/AstreinteFinale/venv/lib/python3.10/site-packages/flask/app.py", line 920, in run
    run_simple(t.cast(str, host), port, self, **options)
  File "/Users/user/Documents/python/AstreinteFinale/venv/lib/python3.10/site-packages/werkzeug/serving.py", line 984, in run_simple
    s.bind(server_address)
OSError: [Errno 48] Address already in use
 * Serving Flask app 'base' (lazy loading)
 * Environment: production
   WARNING: This is a development server. Do not use it in a production deployment.
   Use a production WSGI server instead.
 * Debug mode: on
Traceback (most recent call last):
  File "/Users/user/Documents/python/AstreinteFinale/base.py", line 417, in <module>
    app.run(debug=True, host="127.0.0.1",port=5000)
  File "/Users/user/Documents/python/AstreinteFinale/venv/lib/python3.10/site-packages/flask/app.py", line 920, in run
    run_simple(t.cast(str, host), port, self, **options)
  File "/Users/user/Documents/python/AstreinteFinale/venv/lib/python3.10/site-packages/werkzeug/serving.py", line 984, in run_simple
    s.bind(server_address)
OSError: [Errno 48] Address already in use
127.0.0.1 - - [03/Jan/2022 11:22:09] "GET /astreintes HTTP/1.1" 200 -
 * Serving Flask app 'base' (lazy loading)
 * Environment: production
   WARNING: This is a development server. Do not use it in a production deployment.
   Use a production WSGI server instead.
 * Debug mode: on
Traceback (most recent call last):
  File "/Users/user/Documents/python/AstreinteFinale/base.py", line 417, in <module>
    app.run(debug=True, host="127.0.0.1",port=5000)
  File "/Users/user/Documents/python/AstreinteFinale/venv/lib/python3.10/site-packages/flask/app.py", line 920, in run
    run_simple(t.cast(str, host), port, self, **options)
  File "/Users/user/Documents/python/AstreinteFinale/venv/lib/python3.10/site-packages/werkzeug/serving.py", line 984, in run_simple
    s.bind(server_address)
OSError: [Errno 48] Address already in use
 * Serving Flask app 'base' (lazy loading)
 * Environment: production
   WARNING: This is a development server. Do not use it in a production deployment.
   Use a production WSGI server instead.
 * Debug mode: on
Traceback (most recent call last):
  File "/Users/user/Documents/python/AstreinteFinale/base.py", line 417, in <module>
    app.run(debug=True, host="127.0.0.1",port=5000)
  File "/Users/user/Documents/python/AstreinteFinale/venv/lib/python3.10/site-packages/flask/app.py", line 920, in run
    run_simple(t.cast(str, host), port, self, **options)
  File "/Users/user/Documents/python/AstreinteFinale/venv/lib/python3.10/site-packages/werkzeug/serving.py", line 984, in run_simple
    s.bind(server_address)
OSError: [Errno 48] Address already in use
127.0.0.1 - - [03/Jan/2022 11:24:10] "GET /astreintes HTTP/1.1" 200 -
 * Serving Flask app 'base' (lazy loading)
 * Environment: production
   WARNING: This is a development server. Do not use it in a production deployment.
   Use a production WSGI server instead.
 * Debug mode: on
Traceback (most recent call last):
  File "/Users/user/Documents/python/AstreinteFinale/base.py", line 417, in <module>
    app.run(debug=True, host="127.0.0.1",port=5000)
  File "/Users/user/Documents/python/AstreinteFinale/venv/lib/python3.10/site-packages/flask/app.py", line 920, in run
    run_simple(t.cast(str, host), port, self, **options)
  File "/Users/user/Documents/python/AstreinteFinale/venv/lib/python3.10/site-packages/werkzeug/serving.py", line 984, in run_simple
    s.bind(server_address)
OSError: [Errno 48] Address already in use
 * Serving Flask app 'base' (lazy loading)
 * Environment: production
   WARNING: This is a development server. Do not use it in a production deployment.
   Use a production WSGI server instead.
 * Debug mode: on
Traceback (most recent call last):
  File "/Users/user/Documents/python/AstreinteFinale/base.py", line 417, in <module>
    app.run(debug=True, host="127.0.0.1",port=5000)
  File "/Users/user/Documents/python/AstreinteFinale/venv/lib/python3.10/site-packages/flask/app.py", line 920, in run
    run_simple(t.cast(str, host), port, self, **options)
  File "/Users/user/Documents/python/AstreinteFinale/venv/lib/python3.10/site-packages/werkzeug/serving.py", line 984, in run_simple
    s.bind(server_address)
OSError: [Errno 48] Address already in use
127.0.0.1 - - [03/Jan/2022 11:26:10] "GET /astreintes HTTP/1.1" 200 -
 * Serving Flask app 'base' (lazy loading)
 * Environment: production
   WARNING: This is a development server. Do not use it in a production deployment.
   Use a production WSGI server instead.
 * Debug mode: on
Traceback (most recent call last):
  File "/Users/user/Documents/python/AstreinteFinale/base.py", line 417, in <module>
    app.run(debug=True, host="127.0.0.1",port=5000)
  File "/Users/user/Documents/python/AstreinteFinale/venv/lib/python3.10/site-packages/flask/app.py", line 920, in run
    run_simple(t.cast(str, host), port, self, **options)
  File "/Users/user/Documents/python/AstreinteFinale/venv/lib/python3.10/site-packages/werkzeug/serving.py", line 984, in run_simple
    s.bind(server_address)
OSError: [Errno 48] Address already in use
 * Serving Flask app 'base' (lazy loading)
 * Environment: production
   WARNING: This is a development server. Do not use it in a production deployment.
   Use a production WSGI server instead.
 * Debug mode: on
Traceback (most recent call last):
  File "/Users/user/Documents/python/AstreinteFinale/base.py", line 417, in <module>
    app.run(debug=True, host="127.0.0.1",port=5000)
  File "/Users/user/Documents/python/AstreinteFinale/venv/lib/python3.10/site-packages/flask/app.py", line 920, in run
    run_simple(t.cast(str, host), port, self, **options)
  File "/Users/user/Documents/python/AstreinteFinale/venv/lib/python3.10/site-packages/werkzeug/serving.py", line 984, in run_simple
    s.bind(server_address)
OSError: [Errno 48] Address already in use
127.0.0.1 - - [03/Jan/2022 11:28:12] "GET /astreintes HTTP/1.1" 200 -
 * Serving Flask app 'base' (lazy loading)
 * Environment: production
   WARNING: This is a development server. Do not use it in a production deployment.
   Use a production WSGI server instead.
 * Debug mode: on
Traceback (most recent call last):
  File "/Users/user/Documents/python/AstreinteFinale/base.py", line 417, in <module>
    app.run(debug=True, host="127.0.0.1",port=5000)
  File "/Users/user/Documents/python/AstreinteFinale/venv/lib/python3.10/site-packages/flask/app.py", line 920, in run
    run_simple(t.cast(str, host), port, self, **options)
  File "/Users/user/Documents/python/AstreinteFinale/venv/lib/python3.10/site-packages/werkzeug/serving.py", line 984, in run_simple
    s.bind(server_address)
OSError: [Errno 48] Address already in use
 * Serving Flask app 'base' (lazy loading)
 * Environment: production
   WARNING: This is a development server. Do not use it in a production deployment.
   Use a production WSGI server instead.
 * Debug mode: on
Traceback (most recent call last):
  File "/Users/user/Documents/python/AstreinteFinale/base.py", line 417, in <module>
    app.run(debug=True, host="127.0.0.1",port=5000)
  File "/Users/user/Documents/python/AstreinteFinale/venv/lib/python3.10/site-packages/flask/app.py", line 920, in run
    run_simple(t.cast(str, host), port, self, **options)
  File "/Users/user/Documents/python/AstreinteFinale/venv/lib/python3.10/site-packages/werkzeug/serving.py", line 984, in run_simple
    s.bind(server_address)
OSError: [Errno 48] Address already in use
127.0.0.1 - - [03/Jan/2022 11:30:09] "GET /astreintes HTTP/1.1" 200 -
 * Serving Flask app 'base' (lazy loading)
 * Environment: production
   WARNING: This is a development server. Do not use it in a production deployment.
   Use a production WSGI server instead.
 * Debug mode: on
Traceback (most recent call last):
  File "/Users/user/Documents/python/AstreinteFinale/base.py", line 417, in <module>
    app.run(debug=True, host="127.0.0.1",port=5000)
  File "/Users/user/Documents/python/AstreinteFinale/venv/lib/python3.10/site-packages/flask/app.py", line 920, in run
    run_simple(t.cast(str, host), port, self, **options)
  File "/Users/user/Documents/python/AstreinteFinale/venv/lib/python3.10/site-packages/werkzeug/serving.py", line 984, in run_simple
    s.bind(server_address)
OSError: [Errno 48] Address already in use
 * Serving Flask app 'base' (lazy loading)
 * Environment: production
   WARNING: This is a development server. Do not use it in a production deployment.
   Use a production WSGI server instead.
 * Debug mode: on
Traceback (most recent call last):
  File "/Users/user/Documents/python/AstreinteFinale/base.py", line 417, in <module>
    app.run(debug=True, host="127.0.0.1",port=5000)
  File "/Users/user/Documents/python/AstreinteFinale/venv/lib/python3.10/site-packages/flask/app.py", line 920, in run
    run_simple(t.cast(str, host), port, self, **options)
  File "/Users/user/Documents/python/AstreinteFinale/venv/lib/python3.10/site-packages/werkzeug/serving.py", line 984, in run_simple
    s.bind(server_address)
OSError: [Errno 48] Address already in use
127.0.0.1 - - [03/Jan/2022 11:32:14] "GET /astreintes HTTP/1.1" 200 -
 * Serving Flask app 'base' (lazy loading)
 * Environment: production
   WARNING: This is a development server. Do not use it in a production deployment.
   Use a production WSGI server instead.
 * Debug mode: on
Traceback (most recent call last):
  File "/Users/user/Documents/python/AstreinteFinale/base.py", line 417, in <module>
    app.run(debug=True, host="127.0.0.1",port=5000)
  File "/Users/user/Documents/python/AstreinteFinale/venv/lib/python3.10/site-packages/flask/app.py", line 920, in run
    run_simple(t.cast(str, host), port, self, **options)
  File "/Users/user/Documents/python/AstreinteFinale/venv/lib/python3.10/site-packages/werkzeug/serving.py", line 984, in run_simple
    s.bind(server_address)
OSError: [Errno 48] Address already in use
 * Serving Flask app 'base' (lazy loading)
 * Environment: production
   WARNING: This is a development server. Do not use it in a production deployment.
   Use a production WSGI server instead.
 * Debug mode: on
Traceback (most recent call last):
  File "/Users/user/Documents/python/AstreinteFinale/base.py", line 417, in <module>
    app.run(debug=True, host="127.0.0.1",port=5000)
  File "/Users/user/Documents/python/AstreinteFinale/venv/lib/python3.10/site-packages/flask/app.py", line 920, in run
    run_simple(t.cast(str, host), port, self, **options)
  File "/Users/user/Documents/python/AstreinteFinale/venv/lib/python3.10/site-packages/werkzeug/serving.py", line 984, in run_simple
    s.bind(server_address)
OSError: [Errno 48] Address already in use
127.0.0.1 - - [03/Jan/2022 11:34:09] "GET /astreintes HTTP/1.1" 200 -
 * Serving Flask app 'base' (lazy loading)
 * Environment: production
   WARNING: This is a development server. Do not use it in a production deployment.
   Use a production WSGI server instead.
 * Debug mode: on
Traceback (most recent call last):
  File "/Users/user/Documents/python/AstreinteFinale/base.py", line 417, in <module>
    app.run(debug=True, host="127.0.0.1",port=5000)
  File "/Users/user/Documents/python/AstreinteFinale/venv/lib/python3.10/site-packages/flask/app.py", line 920, in run
    run_simple(t.cast(str, host), port, self, **options)
  File "/Users/user/Documents/python/AstreinteFinale/venv/lib/python3.10/site-packages/werkzeug/serving.py", line 984, in run_simple
    s.bind(server_address)
OSError: [Errno 48] Address already in use
 * Serving Flask app 'base' (lazy loading)
 * Environment: production
   WARNING: This is a development server. Do not use it in a production deployment.
   Use a production WSGI server instead.
 * Debug mode: on
Traceback (most recent call last):
  File "/Users/user/Documents/python/AstreinteFinale/base.py", line 417, in <module>
    app.run(debug=True, host="127.0.0.1",port=5000)
  File "/Users/user/Documents/python/AstreinteFinale/venv/lib/python3.10/site-packages/flask/app.py", line 920, in run
    run_simple(t.cast(str, host), port, self, **options)
  File "/Users/user/Documents/python/AstreinteFinale/venv/lib/python3.10/site-packages/werkzeug/serving.py", line 984, in run_simple
    s.bind(server_address)
OSError: [Errno 48] Address already in use
127.0.0.1 - - [03/Jan/2022 11:36:10] "GET /astreintes HTTP/1.1" 200 -
 * Serving Flask app 'base' (lazy loading)
 * Environment: production
   WARNING: This is a development server. Do not use it in a production deployment.
   Use a production WSGI server instead.
 * Debug mode: on
Traceback (most recent call last):
  File "/Users/user/Documents/python/AstreinteFinale/base.py", line 417, in <module>
    app.run(debug=True, host="127.0.0.1",port=5000)
  File "/Users/user/Documents/python/AstreinteFinale/venv/lib/python3.10/site-packages/flask/app.py", line 920, in run
    run_simple(t.cast(str, host), port, self, **options)
  File "/Users/user/Documents/python/AstreinteFinale/venv/lib/python3.10/site-packages/werkzeug/serving.py", line 984, in run_simple
    s.bind(server_address)
OSError: [Errno 48] Address already in use
 * Serving Flask app 'base' (lazy loading)
 * Environment: production
   WARNING: This is a development server. Do not use it in a production deployment.
   Use a production WSGI server instead.
 * Debug mode: on
Traceback (most recent call last):
  File "/Users/user/Documents/python/AstreinteFinale/base.py", line 417, in <module>
    app.run(debug=True, host="127.0.0.1",port=5000)
  File "/Users/user/Documents/python/AstreinteFinale/venv/lib/python3.10/site-packages/flask/app.py", line 920, in run
    run_simple(t.cast(str, host), port, self, **options)
  File "/Users/user/Documents/python/AstreinteFinale/venv/lib/python3.10/site-packages/werkzeug/serving.py", line 984, in run_simple
    s.bind(server_address)
OSError: [Errno 48] Address already in use
127.0.0.1 - - [03/Jan/2022 11:38:12] "GET /astreintes HTTP/1.1" 200 -
 * Serving Flask app 'base' (lazy loading)
 * Environment: production
   WARNING: This is a development server. Do not use it in a production deployment.
   Use a production WSGI server instead.
 * Debug mode: on
Traceback (most recent call last):
  File "/Users/user/Documents/python/AstreinteFinale/base.py", line 417, in <module>
    app.run(debug=True, host="127.0.0.1",port=5000)
  File "/Users/user/Documents/python/AstreinteFinale/venv/lib/python3.10/site-packages/flask/app.py", line 920, in run
    run_simple(t.cast(str, host), port, self, **options)
  File "/Users/user/Documents/python/AstreinteFinale/venv/lib/python3.10/site-packages/werkzeug/serving.py", line 984, in run_simple
    s.bind(server_address)
OSError: [Errno 48] Address already in use
 * Serving Flask app 'base' (lazy loading)
 * Environment: production
   WARNING: This is a development server. Do not use it in a production deployment.
   Use a production WSGI server instead.
 * Debug mode: on
Traceback (most recent call last):
  File "/Users/user/Documents/python/AstreinteFinale/base.py", line 417, in <module>
    app.run(debug=True, host="127.0.0.1",port=5000)
  File "/Users/user/Documents/python/AstreinteFinale/venv/lib/python3.10/site-packages/flask/app.py", line 920, in run
    run_simple(t.cast(str, host), port, self, **options)
  File "/Users/user/Documents/python/AstreinteFinale/venv/lib/python3.10/site-packages/werkzeug/serving.py", line 984, in run_simple
    s.bind(server_address)
OSError: [Errno 48] Address already in use
127.0.0.1 - - [03/Jan/2022 11:40:11] "GET /astreintes HTTP/1.1" 200 -
 * Serving Flask app 'base' (lazy loading)
 * Environment: production
   WARNING: This is a development server. Do not use it in a production deployment.
   Use a production WSGI server instead.
 * Debug mode: on
Traceback (most recent call last):
  File "/Users/user/Documents/python/AstreinteFinale/base.py", line 417, in <module>
    app.run(debug=True, host="127.0.0.1",port=5000)
  File "/Users/user/Documents/python/AstreinteFinale/venv/lib/python3.10/site-packages/flask/app.py", line 920, in run
    run_simple(t.cast(str, host), port, self, **options)
  File "/Users/user/Documents/python/AstreinteFinale/venv/lib/python3.10/site-packages/werkzeug/serving.py", line 984, in run_simple
    s.bind(server_address)
OSError: [Errno 48] Address already in use
 * Serving Flask app 'base' (lazy loading)
 * Environment: production
   WARNING: This is a development server. Do not use it in a production deployment.
   Use a production WSGI server instead.
 * Debug mode: on
Traceback (most recent call last):
  File "/Users/user/Documents/python/AstreinteFinale/base.py", line 417, in <module>
    app.run(debug=True, host="127.0.0.1",port=5000)
  File "/Users/user/Documents/python/AstreinteFinale/venv/lib/python3.10/site-packages/flask/app.py", line 920, in run
    run_simple(t.cast(str, host), port, self, **options)
  File "/Users/user/Documents/python/AstreinteFinale/venv/lib/python3.10/site-packages/werkzeug/serving.py", line 984, in run_simple
    s.bind(server_address)
OSError: [Errno 48] Address already in use
127.0.0.1 - - [03/Jan/2022 11:42:09] "GET /astreintes HTTP/1.1" 200 -
 * Serving Flask app 'base' (lazy loading)
 * Environment: production
   WARNING: This is a development server. Do not use it in a production deployment.
   Use a production WSGI server instead.
 * Debug mode: on
Traceback (most recent call last):
  File "/Users/user/Documents/python/AstreinteFinale/base.py", line 417, in <module>
    app.run(debug=True, host="127.0.0.1",port=5000)
  File "/Users/user/Documents/python/AstreinteFinale/venv/lib/python3.10/site-packages/flask/app.py", line 920, in run
    run_simple(t.cast(str, host), port, self, **options)
  File "/Users/user/Documents/python/AstreinteFinale/venv/lib/python3.10/site-packages/werkzeug/serving.py", line 984, in run_simple
    s.bind(server_address)
OSError: [Errno 48] Address already in use
 * Serving Flask app 'base' (lazy loading)
 * Environment: production
   WARNING: This is a development server. Do not use it in a production deployment.
   Use a production WSGI server instead.
 * Debug mode: on
Traceback (most recent call last):
  File "/Users/user/Documents/python/AstreinteFinale/base.py", line 417, in <module>
    app.run(debug=True, host="127.0.0.1",port=5000)
  File "/Users/user/Documents/python/AstreinteFinale/venv/lib/python3.10/site-packages/flask/app.py", line 920, in run
    run_simple(t.cast(str, host), port, self, **options)
  File "/Users/user/Documents/python/AstreinteFinale/venv/lib/python3.10/site-packages/werkzeug/serving.py", line 984, in run_simple
    s.bind(server_address)
OSError: [Errno 48] Address already in use
127.0.0.1 - - [03/Jan/2022 11:44:12] "GET /astreintes HTTP/1.1" 200 -
 * Serving Flask app 'base' (lazy loading)
 * Environment: production
   WARNING: This is a development server. Do not use it in a production deployment.
   Use a production WSGI server instead.
 * Debug mode: on
Traceback (most recent call last):
  File "/Users/user/Documents/python/AstreinteFinale/base.py", line 417, in <module>
    app.run(debug=True, host="127.0.0.1",port=5000)
  File "/Users/user/Documents/python/AstreinteFinale/venv/lib/python3.10/site-packages/flask/app.py", line 920, in run
    run_simple(t.cast(str, host), port, self, **options)
  File "/Users/user/Documents/python/AstreinteFinale/venv/lib/python3.10/site-packages/werkzeug/serving.py", line 984, in run_simple
    s.bind(server_address)
OSError: [Errno 48] Address already in use
 * Serving Flask app 'base' (lazy loading)
 * Environment: production
   WARNING: This is a development server. Do not use it in a production deployment.
   Use a production WSGI server instead.
 * Debug mode: on
Traceback (most recent call last):
  File "/Users/user/Documents/python/AstreinteFinale/base.py", line 417, in <module>
    app.run(debug=True, host="127.0.0.1",port=5000)
  File "/Users/user/Documents/python/AstreinteFinale/venv/lib/python3.10/site-packages/flask/app.py", line 920, in run
    run_simple(t.cast(str, host), port, self, **options)
  File "/Users/user/Documents/python/AstreinteFinale/venv/lib/python3.10/site-packages/werkzeug/serving.py", line 984, in run_simple
    s.bind(server_address)
OSError: [Errno 48] Address already in use
127.0.0.1 - - [03/Jan/2022 11:46:12] "GET /astreintes HTTP/1.1" 200 -
 * Serving Flask app 'base' (lazy loading)
 * Environment: production
   WARNING: This is a development server. Do not use it in a production deployment.
   Use a production WSGI server instead.
 * Debug mode: on
Traceback (most recent call last):
  File "/Users/user/Documents/python/AstreinteFinale/base.py", line 417, in <module>
    app.run(debug=True, host="127.0.0.1",port=5000)
  File "/Users/user/Documents/python/AstreinteFinale/venv/lib/python3.10/site-packages/flask/app.py", line 920, in run
    run_simple(t.cast(str, host), port, self, **options)
  File "/Users/user/Documents/python/AstreinteFinale/venv/lib/python3.10/site-packages/werkzeug/serving.py", line 984, in run_simple
    s.bind(server_address)
OSError: [Errno 48] Address already in use
 * Serving Flask app 'base' (lazy loading)
 * Environment: production
   WARNING: This is a development server. Do not use it in a production deployment.
   Use a production WSGI server instead.
 * Debug mode: on
Traceback (most recent call last):
  File "/Users/user/Documents/python/AstreinteFinale/base.py", line 417, in <module>
    app.run(debug=True, host="127.0.0.1",port=5000)
  File "/Users/user/Documents/python/AstreinteFinale/venv/lib/python3.10/site-packages/flask/app.py", line 920, in run
    run_simple(t.cast(str, host), port, self, **options)
  File "/Users/user/Documents/python/AstreinteFinale/venv/lib/python3.10/site-packages/werkzeug/serving.py", line 984, in run_simple
    s.bind(server_address)
OSError: [Errno 48] Address already in use
127.0.0.1 - - [03/Jan/2022 11:48:10] "GET /astreintes HTTP/1.1" 200 -
 * Serving Flask app 'base' (lazy loading)
 * Environment: production
   WARNING: This is a development server. Do not use it in a production deployment.
   Use a production WSGI server instead.
 * Debug mode: on
Traceback (most recent call last):
  File "/Users/user/Documents/python/AstreinteFinale/base.py", line 417, in <module>
    app.run(debug=True, host="127.0.0.1",port=5000)
  File "/Users/user/Documents/python/AstreinteFinale/venv/lib/python3.10/site-packages/flask/app.py", line 920, in run
    run_simple(t.cast(str, host), port, self, **options)
  File "/Users/user/Documents/python/AstreinteFinale/venv/lib/python3.10/site-packages/werkzeug/serving.py", line 984, in run_simple
    s.bind(server_address)
OSError: [Errno 48] Address already in use
 * Serving Flask app 'base' (lazy loading)
 * Environment: production
   WARNING: This is a development server. Do not use it in a production deployment.
   Use a production WSGI server instead.
 * Debug mode: on
Traceback (most recent call last):
  File "/Users/user/Documents/python/AstreinteFinale/base.py", line 417, in <module>
    app.run(debug=True, host="127.0.0.1",port=5000)
  File "/Users/user/Documents/python/AstreinteFinale/venv/lib/python3.10/site-packages/flask/app.py", line 920, in run
    run_simple(t.cast(str, host), port, self, **options)
  File "/Users/user/Documents/python/AstreinteFinale/venv/lib/python3.10/site-packages/werkzeug/serving.py", line 984, in run_simple
    s.bind(server_address)
OSError: [Errno 48] Address already in use
127.0.0.1 - - [03/Jan/2022 11:50:10] "GET /astreintes HTTP/1.1" 200 -
 * Serving Flask app 'base' (lazy loading)
 * Environment: production
   WARNING: This is a development server. Do not use it in a production deployment.
   Use a production WSGI server instead.
 * Debug mode: on
Traceback (most recent call last):
  File "/Users/user/Documents/python/AstreinteFinale/base.py", line 417, in <module>
    app.run(debug=True, host="127.0.0.1",port=5000)
  File "/Users/user/Documents/python/AstreinteFinale/venv/lib/python3.10/site-packages/flask/app.py", line 920, in run
    run_simple(t.cast(str, host), port, self, **options)
  File "/Users/user/Documents/python/AstreinteFinale/venv/lib/python3.10/site-packages/werkzeug/serving.py", line 984, in run_simple
    s.bind(server_address)
OSError: [Errno 48] Address already in use
 * Serving Flask app 'base' (lazy loading)
 * Environment: production
   WARNING: This is a development server. Do not use it in a production deployment.
   Use a production WSGI server instead.
 * Debug mode: on
Traceback (most recent call last):
  File "/Users/user/Documents/python/AstreinteFinale/base.py", line 417, in <module>
    app.run(debug=True, host="127.0.0.1",port=5000)
  File "/Users/user/Documents/python/AstreinteFinale/venv/lib/python3.10/site-packages/flask/app.py", line 920, in run
    run_simple(t.cast(str, host), port, self, **options)
  File "/Users/user/Documents/python/AstreinteFinale/venv/lib/python3.10/site-packages/werkzeug/serving.py", line 984, in run_simple
    s.bind(server_address)
OSError: [Errno 48] Address already in use
127.0.0.1 - - [03/Jan/2022 11:52:10] "GET /astreintes HTTP/1.1" 200 -
 * Serving Flask app 'base' (lazy loading)
 * Environment: production
   WARNING: This is a development server. Do not use it in a production deployment.
   Use a production WSGI server instead.
 * Debug mode: on
Traceback (most recent call last):
  File "/Users/user/Documents/python/AstreinteFinale/base.py", line 417, in <module>
    app.run(debug=True, host="127.0.0.1",port=5000)
  File "/Users/user/Documents/python/AstreinteFinale/venv/lib/python3.10/site-packages/flask/app.py", line 920, in run
    run_simple(t.cast(str, host), port, self, **options)
  File "/Users/user/Documents/python/AstreinteFinale/venv/lib/python3.10/site-packages/werkzeug/serving.py", line 984, in run_simple
    s.bind(server_address)
OSError: [Errno 48] Address already in use
 * Serving Flask app 'base' (lazy loading)
 * Environment: production
   WARNING: This is a development server. Do not use it in a production deployment.
   Use a production WSGI server instead.
 * Debug mode: on
Traceback (most recent call last):
  File "/Users/user/Documents/python/AstreinteFinale/base.py", line 417, in <module>
    app.run(debug=True, host="127.0.0.1",port=5000)
  File "/Users/user/Documents/python/AstreinteFinale/venv/lib/python3.10/site-packages/flask/app.py", line 920, in run
    run_simple(t.cast(str, host), port, self, **options)
  File "/Users/user/Documents/python/AstreinteFinale/venv/lib/python3.10/site-packages/werkzeug/serving.py", line 984, in run_simple
    s.bind(server_address)
OSError: [Errno 48] Address already in use
127.0.0.1 - - [03/Jan/2022 11:54:09] "GET /astreintes HTTP/1.1" 200 -
 * Serving Flask app 'base' (lazy loading)
 * Environment: production
   WARNING: This is a development server. Do not use it in a production deployment.
   Use a production WSGI server instead.
 * Debug mode: on
Traceback (most recent call last):
  File "/Users/user/Documents/python/AstreinteFinale/base.py", line 417, in <module>
    app.run(debug=True, host="127.0.0.1",port=5000)
  File "/Users/user/Documents/python/AstreinteFinale/venv/lib/python3.10/site-packages/flask/app.py", line 920, in run
    run_simple(t.cast(str, host), port, self, **options)
  File "/Users/user/Documents/python/AstreinteFinale/venv/lib/python3.10/site-packages/werkzeug/serving.py", line 984, in run_simple
    s.bind(server_address)
OSError: [Errno 48] Address already in use
 * Serving Flask app 'base' (lazy loading)
 * Environment: production
   WARNING: This is a development server. Do not use it in a production deployment.
   Use a production WSGI server instead.
 * Debug mode: on
Traceback (most recent call last):
  File "/Users/user/Documents/python/AstreinteFinale/base.py", line 417, in <module>
    app.run(debug=True, host="127.0.0.1",port=5000)
  File "/Users/user/Documents/python/AstreinteFinale/venv/lib/python3.10/site-packages/flask/app.py", line 920, in run
    run_simple(t.cast(str, host), port, self, **options)
  File "/Users/user/Documents/python/AstreinteFinale/venv/lib/python3.10/site-packages/werkzeug/serving.py", line 984, in run_simple
    s.bind(server_address)
OSError: [Errno 48] Address already in use
127.0.0.1 - - [03/Jan/2022 11:56:13] "GET /astreintes HTTP/1.1" 200 -
 * Serving Flask app 'base' (lazy loading)
 * Environment: production
   WARNING: This is a development server. Do not use it in a production deployment.
   Use a production WSGI server instead.
 * Debug mode: on
Traceback (most recent call last):
  File "/Users/user/Documents/python/AstreinteFinale/base.py", line 417, in <module>
    app.run(debug=True, host="127.0.0.1",port=5000)
  File "/Users/user/Documents/python/AstreinteFinale/venv/lib/python3.10/site-packages/flask/app.py", line 920, in run
    run_simple(t.cast(str, host), port, self, **options)
  File "/Users/user/Documents/python/AstreinteFinale/venv/lib/python3.10/site-packages/werkzeug/serving.py", line 984, in run_simple
    s.bind(server_address)
OSError: [Errno 48] Address already in use
 * Serving Flask app 'base' (lazy loading)
 * Environment: production
   WARNING: This is a development server. Do not use it in a production deployment.
   Use a production WSGI server instead.
 * Debug mode: on
Traceback (most recent call last):
  File "/Users/user/Documents/python/AstreinteFinale/base.py", line 417, in <module>
    app.run(debug=True, host="127.0.0.1",port=5000)
  File "/Users/user/Documents/python/AstreinteFinale/venv/lib/python3.10/site-packages/flask/app.py", line 920, in run
    run_simple(t.cast(str, host), port, self, **options)
  File "/Users/user/Documents/python/AstreinteFinale/venv/lib/python3.10/site-packages/werkzeug/serving.py", line 984, in run_simple
    s.bind(server_address)
OSError: [Errno 48] Address already in use
127.0.0.1 - - [03/Jan/2022 11:58:09] "GET /astreintes HTTP/1.1" 200 -
 * Serving Flask app 'base' (lazy loading)
 * Environment: production
   WARNING: This is a development server. Do not use it in a production deployment.
   Use a production WSGI server instead.
 * Debug mode: on
Traceback (most recent call last):
  File "/Users/user/Documents/python/AstreinteFinale/base.py", line 417, in <module>
    app.run(debug=True, host="127.0.0.1",port=5000)
  File "/Users/user/Documents/python/AstreinteFinale/venv/lib/python3.10/site-packages/flask/app.py", line 920, in run
    run_simple(t.cast(str, host), port, self, **options)
  File "/Users/user/Documents/python/AstreinteFinale/venv/lib/python3.10/site-packages/werkzeug/serving.py", line 984, in run_simple
    s.bind(server_address)
OSError: [Errno 48] Address already in use
 * Serving Flask app 'base' (lazy loading)
 * Environment: production
   WARNING: This is a development server. Do not use it in a production deployment.
   Use a production WSGI server instead.
 * Debug mode: on
Traceback (most recent call last):
  File "/Users/user/Documents/python/AstreinteFinale/base.py", line 417, in <module>
    app.run(debug=True, host="127.0.0.1",port=5000)
  File "/Users/user/Documents/python/AstreinteFinale/venv/lib/python3.10/site-packages/flask/app.py", line 920, in run
    run_simple(t.cast(str, host), port, self, **options)
  File "/Users/user/Documents/python/AstreinteFinale/venv/lib/python3.10/site-packages/werkzeug/serving.py", line 984, in run_simple
    s.bind(server_address)
OSError: [Errno 48] Address already in use
127.0.0.1 - - [03/Jan/2022 12:00:12] "GET /astreintes HTTP/1.1" 200 -
 * Serving Flask app 'base' (lazy loading)
 * Environment: production
   WARNING: This is a development server. Do not use it in a production deployment.
   Use a production WSGI server instead.
 * Debug mode: on
Traceback (most recent call last):
  File "/Users/user/Documents/python/AstreinteFinale/base.py", line 417, in <module>
    app.run(debug=True, host="127.0.0.1",port=5000)
  File "/Users/user/Documents/python/AstreinteFinale/venv/lib/python3.10/site-packages/flask/app.py", line 920, in run
    run_simple(t.cast(str, host), port, self, **options)
  File "/Users/user/Documents/python/AstreinteFinale/venv/lib/python3.10/site-packages/werkzeug/serving.py", line 984, in run_simple
    s.bind(server_address)
OSError: [Errno 48] Address already in use
 * Serving Flask app 'base' (lazy loading)
 * Environment: production
   WARNING: This is a development server. Do not use it in a production deployment.
   Use a production WSGI server instead.
 * Debug mode: on
Traceback (most recent call last):
  File "/Users/user/Documents/python/AstreinteFinale/base.py", line 417, in <module>
    app.run(debug=True, host="127.0.0.1",port=5000)
  File "/Users/user/Documents/python/AstreinteFinale/venv/lib/python3.10/site-packages/flask/app.py", line 920, in run
    run_simple(t.cast(str, host), port, self, **options)
  File "/Users/user/Documents/python/AstreinteFinale/venv/lib/python3.10/site-packages/werkzeug/serving.py", line 984, in run_simple
    s.bind(server_address)
OSError: [Errno 48] Address already in use
127.0.0.1 - - [03/Jan/2022 12:02:14] "GET /astreintes HTTP/1.1" 200 -
 * Serving Flask app 'base' (lazy loading)
 * Environment: production
   WARNING: This is a development server. Do not use it in a production deployment.
   Use a production WSGI server instead.
 * Debug mode: on
Traceback (most recent call last):
  File "/Users/user/Documents/python/AstreinteFinale/base.py", line 417, in <module>
    app.run(debug=True, host="127.0.0.1",port=5000)
  File "/Users/user/Documents/python/AstreinteFinale/venv/lib/python3.10/site-packages/flask/app.py", line 920, in run
    run_simple(t.cast(str, host), port, self, **options)
  File "/Users/user/Documents/python/AstreinteFinale/venv/lib/python3.10/site-packages/werkzeug/serving.py", line 984, in run_simple
    s.bind(server_address)
OSError: [Errno 48] Address already in use
 * Serving Flask app 'base' (lazy loading)
 * Environment: production
   WARNING: This is a development server. Do not use it in a production deployment.
   Use a production WSGI server instead.
 * Debug mode: on
Traceback (most recent call last):
  File "/Users/user/Documents/python/AstreinteFinale/base.py", line 417, in <module>
    app.run(debug=True, host="127.0.0.1",port=5000)
  File "/Users/user/Documents/python/AstreinteFinale/venv/lib/python3.10/site-packages/flask/app.py", line 920, in run
    run_simple(t.cast(str, host), port, self, **options)
  File "/Users/user/Documents/python/AstreinteFinale/venv/lib/python3.10/site-packages/werkzeug/serving.py", line 984, in run_simple
    s.bind(server_address)
OSError: [Errno 48] Address already in use
127.0.0.1 - - [03/Jan/2022 12:04:12] "GET /astreintes HTTP/1.1" 200 -
 * Serving Flask app 'base' (lazy loading)
 * Environment: production
   WARNING: This is a development server. Do not use it in a production deployment.
   Use a production WSGI server instead.
 * Debug mode: on
Traceback (most recent call last):
  File "/Users/user/Documents/python/AstreinteFinale/base.py", line 417, in <module>
    app.run(debug=True, host="127.0.0.1",port=5000)
  File "/Users/user/Documents/python/AstreinteFinale/venv/lib/python3.10/site-packages/flask/app.py", line 920, in run
    run_simple(t.cast(str, host), port, self, **options)
  File "/Users/user/Documents/python/AstreinteFinale/venv/lib/python3.10/site-packages/werkzeug/serving.py", line 984, in run_simple
    s.bind(server_address)
OSError: [Errno 48] Address already in use
 * Serving Flask app 'base' (lazy loading)
 * Environment: production
   WARNING: This is a development server. Do not use it in a production deployment.
   Use a production WSGI server instead.
 * Debug mode: on
Traceback (most recent call last):
  File "/Users/user/Documents/python/AstreinteFinale/base.py", line 417, in <module>
    app.run(debug=True, host="127.0.0.1",port=5000)
  File "/Users/user/Documents/python/AstreinteFinale/venv/lib/python3.10/site-packages/flask/app.py", line 920, in run
    run_simple(t.cast(str, host), port, self, **options)
  File "/Users/user/Documents/python/AstreinteFinale/venv/lib/python3.10/site-packages/werkzeug/serving.py", line 984, in run_simple
    s.bind(server_address)
OSError: [Errno 48] Address already in use
127.0.0.1 - - [03/Jan/2022 12:06:10] "GET /astreintes HTTP/1.1" 200 -
 * Serving Flask app 'base' (lazy loading)
 * Environment: production
   WARNING: This is a development server. Do not use it in a production deployment.
   Use a production WSGI server instead.
 * Debug mode: on
Traceback (most recent call last):
  File "/Users/user/Documents/python/AstreinteFinale/base.py", line 417, in <module>
    app.run(debug=True, host="127.0.0.1",port=5000)
  File "/Users/user/Documents/python/AstreinteFinale/venv/lib/python3.10/site-packages/flask/app.py", line 920, in run
    run_simple(t.cast(str, host), port, self, **options)
  File "/Users/user/Documents/python/AstreinteFinale/venv/lib/python3.10/site-packages/werkzeug/serving.py", line 984, in run_simple
    s.bind(server_address)
OSError: [Errno 48] Address already in use
 * Serving Flask app 'base' (lazy loading)
 * Environment: production
   WARNING: This is a development server. Do not use it in a production deployment.
   Use a production WSGI server instead.
 * Debug mode: on
Traceback (most recent call last):
  File "/Users/user/Documents/python/AstreinteFinale/base.py", line 417, in <module>
    app.run(debug=True, host="127.0.0.1",port=5000)
  File "/Users/user/Documents/python/AstreinteFinale/venv/lib/python3.10/site-packages/flask/app.py", line 920, in run
    run_simple(t.cast(str, host), port, self, **options)
  File "/Users/user/Documents/python/AstreinteFinale/venv/lib/python3.10/site-packages/werkzeug/serving.py", line 984, in run_simple
    s.bind(server_address)
OSError: [Errno 48] Address already in use
 * Detected change in '/Users/user/Documents/python/AstreinteFinale/base.py', reloading
 * Detected change in '/Users/user/Documents/python/AstreinteFinale/base.py', reloading
 * Restarting with stat
 * Restarting with stat
 * Serving Flask app 'base' (lazy loading)
 * Environment: production
   WARNING: This is a development server. Do not use it in a production deployment.
   Use a production WSGI server instead.
 * Debug mode: on
 * Debugger is active!
 * Debugger is active!
Traceback (most recent call last):
  File "/Users/user/Documents/python/AstreinteFinale/base.py", line 417, in <module>
    app.run(debug=True, host="127.0.0.1",port=5000)
  File "/Users/user/Documents/python/AstreinteFinale/venv/lib/python3.10/site-packages/flask/app.py", line 920, in run
    run_simple(t.cast(str, host), port, self, **options)
  File "/Users/user/Documents/python/AstreinteFinale/venv/lib/python3.10/site-packages/werkzeug/serving.py", line 984, in run_simple
 * Debugger PIN: 655-285-932
 * Debugger PIN: 655-285-932
    s.bind(server_address)
OSError: [Errno 48] Address already in use
127.0.0.1 - - [03/Jan/2022 12:08:34] "GET /initiale HTTP/1.1" 200 -
127.0.0.1 - - [03/Jan/2022 12:08:41] "[35m[1mGET /astreintes HTTP/1.1[0m" 500 -
Traceback (most recent call last):
  File "/Users/user/Documents/python/AstreinteFinale/venv/lib/python3.10/site-packages/sqlalchemy/engine/base.py", line 1802, in _execute_context
    self.dialect.do_execute(
  File "/Users/user/Documents/python/AstreinteFinale/venv/lib/python3.10/site-packages/sqlalchemy/engine/default.py", line 732, in do_execute
    cursor.execute(statement, parameters)
  File "/Users/user/Documents/python/AstreinteFinale/venv/lib/python3.10/site-packages/pymysql/cursors.py", line 148, in execute
    result = self._query(query)
  File "/Users/user/Documents/python/AstreinteFinale/venv/lib/python3.10/site-packages/pymysql/cursors.py", line 310, in _query
    conn.query(q)
  File "/Users/user/Documents/python/AstreinteFinale/venv/lib/python3.10/site-packages/pymysql/connections.py", line 548, in query
    self._affected_rows = self._read_query_result(unbuffered=unbuffered)
  File "/Users/user/Documents/python/AstreinteFinale/venv/lib/python3.10/site-packages/pymysql/connections.py", line 775, in _read_query_result
    result.read()
  File "/Users/user/Documents/python/AstreinteFinale/venv/lib/python3.10/site-packages/pymysql/connections.py", line 1156, in read
    first_packet = self.connection._read_packet()
  File "/Users/user/Documents/python/AstreinteFinale/venv/lib/python3.10/site-packages/pymysql/connections.py", line 725, in _read_packet
    packet.raise_for_error()
  File "/Users/user/Documents/python/AstreinteFinale/venv/lib/python3.10/site-packages/pymysql/protocol.py", line 221, in raise_for_error
    err.raise_mysql_exception(self._data)
  File "/Users/user/Documents/python/AstreinteFinale/venv/lib/python3.10/site-packages/pymysql/err.py", line 143, in raise_mysql_exception
    raise errorclass(errno, errval)
pymysql.err.OperationalError: (1364, "Field 'id' doesn't have a default value")

The above exception was the direct cause of the following exception:

Traceback (most recent call last):
  File "/Users/user/Documents/python/AstreinteFinale/venv/lib/python3.10/site-packages/flask/app.py", line 2091, in __call__
    return self.wsgi_app(environ, start_response)
  File "/Users/user/Documents/python/AstreinteFinale/venv/lib/python3.10/site-packages/flask/app.py", line 2076, in wsgi_app
    response = self.handle_exception(e)
  File "/Users/user/Documents/python/AstreinteFinale/venv/lib/python3.10/site-packages/flask/app.py", line 2073, in wsgi_app
    response = self.full_dispatch_request()
  File "/Users/user/Documents/python/AstreinteFinale/venv/lib/python3.10/site-packages/flask/app.py", line 1518, in full_dispatch_request
    rv = self.handle_user_exception(e)
  File "/Users/user/Documents/python/AstreinteFinale/venv/lib/python3.10/site-packages/flask/app.py", line 1516, in full_dispatch_request
    rv = self.dispatch_request()
  File "/Users/user/Documents/python/AstreinteFinale/venv/lib/python3.10/site-packages/flask/app.py", line 1502, in dispatch_request
    return self.ensure_sync(self.view_functions[rule.endpoint])(**req.view_args)
  File "/Users/user/Documents/python/AstreinteFinale/base.py", line 274, in send
    Commite(historique)
  File "/Users/user/Documents/python/AstreinteFinale/base.py", line 378, in Commite
    db.session.commit()
  File "<string>", line 2, in commit
    
  File "/Users/user/Documents/python/AstreinteFinale/venv/lib/python3.10/site-packages/sqlalchemy/orm/session.py", line 1431, in commit
    self._transaction.commit(_to_root=self.future)
  File "/Users/user/Documents/python/AstreinteFinale/venv/lib/python3.10/site-packages/sqlalchemy/orm/session.py", line 829, in commit
    self._prepare_impl()
  File "/Users/user/Documents/python/AstreinteFinale/venv/lib/python3.10/site-packages/sqlalchemy/orm/session.py", line 808, in _prepare_impl
    self.session.flush()
  File "/Users/user/Documents/python/AstreinteFinale/venv/lib/python3.10/site-packages/sqlalchemy/orm/session.py", line 3363, in flush
    self._flush(objects)
  File "/Users/user/Documents/python/AstreinteFinale/venv/lib/python3.10/site-packages/sqlalchemy/orm/session.py", line 3502, in _flush
    with util.safe_reraise():
  File "/Users/user/Documents/python/AstreinteFinale/venv/lib/python3.10/site-packages/sqlalchemy/util/langhelpers.py", line 70, in __exit__
    compat.raise_(
  File "/Users/user/Documents/python/AstreinteFinale/venv/lib/python3.10/site-packages/sqlalchemy/util/compat.py", line 207, in raise_
    raise exception
  File "/Users/user/Documents/python/AstreinteFinale/venv/lib/python3.10/site-packages/sqlalchemy/orm/session.py", line 3463, in _flush
    flush_context.execute()
  File "/Users/user/Documents/python/AstreinteFinale/venv/lib/python3.10/site-packages/sqlalchemy/orm/unitofwork.py", line 456, in execute
    rec.execute(self)
  File "/Users/user/Documents/python/AstreinteFinale/venv/lib/python3.10/site-packages/sqlalchemy/orm/unitofwork.py", line 630, in execute
    util.preloaded.orm_persistence.save_obj(
  File "/Users/user/Documents/python/AstreinteFinale/venv/lib/python3.10/site-packages/sqlalchemy/orm/persistence.py", line 244, in save_obj
    _emit_insert_statements(
  File "/Users/user/Documents/python/AstreinteFinale/venv/lib/python3.10/site-packages/sqlalchemy/orm/persistence.py", line 1221, in _emit_insert_statements
    result = connection._execute_20(
  File "/Users/user/Documents/python/AstreinteFinale/venv/lib/python3.10/site-packages/sqlalchemy/engine/base.py", line 1614, in _execute_20
    return meth(self, args_10style, kwargs_10style, execution_options)
  File "/Users/user/Documents/python/AstreinteFinale/venv/lib/python3.10/site-packages/sqlalchemy/sql/elements.py", line 325, in _execute_on_connection
    return connection._execute_clauseelement(
  File "/Users/user/Documents/python/AstreinteFinale/venv/lib/python3.10/site-packages/sqlalchemy/engine/base.py", line 1481, in _execute_clauseelement
    ret = self._execute_context(
  File "/Users/user/Documents/python/AstreinteFinale/venv/lib/python3.10/site-packages/sqlalchemy/engine/base.py", line 1845, in _execute_context
    self._handle_dbapi_exception(
  File "/Users/user/Documents/python/AstreinteFinale/venv/lib/python3.10/site-packages/sqlalchemy/engine/base.py", line 2026, in _handle_dbapi_exception
    util.raise_(
  File "/Users/user/Documents/python/AstreinteFinale/venv/lib/python3.10/site-packages/sqlalchemy/util/compat.py", line 207, in raise_
    raise exception
  File "/Users/user/Documents/python/AstreinteFinale/venv/lib/python3.10/site-packages/sqlalchemy/engine/base.py", line 1802, in _execute_context
    self.dialect.do_execute(
  File "/Users/user/Documents/python/AstreinteFinale/venv/lib/python3.10/site-packages/sqlalchemy/engine/default.py", line 732, in do_execute
    cursor.execute(statement, parameters)
  File "/Users/user/Documents/python/AstreinteFinale/venv/lib/python3.10/site-packages/pymysql/cursors.py", line 148, in execute
    result = self._query(query)
  File "/Users/user/Documents/python/AstreinteFinale/venv/lib/python3.10/site-packages/pymysql/cursors.py", line 310, in _query
    conn.query(q)
  File "/Users/user/Documents/python/AstreinteFinale/venv/lib/python3.10/site-packages/pymysql/connections.py", line 548, in query
    self._affected_rows = self._read_query_result(unbuffered=unbuffered)
  File "/Users/user/Documents/python/AstreinteFinale/venv/lib/python3.10/site-packages/pymysql/connections.py", line 775, in _read_query_result
    result.read()
  File "/Users/user/Documents/python/AstreinteFinale/venv/lib/python3.10/site-packages/pymysql/connections.py", line 1156, in read
    first_packet = self.connection._read_packet()
  File "/Users/user/Documents/python/AstreinteFinale/venv/lib/python3.10/site-packages/pymysql/connections.py", line 725, in _read_packet
    packet.raise_for_error()
  File "/Users/user/Documents/python/AstreinteFinale/venv/lib/python3.10/site-packages/pymysql/protocol.py", line 221, in raise_for_error
    err.raise_mysql_exception(self._data)
  File "/Users/user/Documents/python/AstreinteFinale/venv/lib/python3.10/site-packages/pymysql/err.py", line 143, in raise_mysql_exception
    raise errorclass(errno, errval)
sqlalchemy.exc.OperationalError: (pymysql.err.OperationalError) (1364, "Field 'id' doesn't have a default value")
[SQL: INSERT INTO historique (astreinte_id, date_debut, date_fin) VALUES (%(astreinte_id)s, %(date_debut)s, %(date_fin)s)]
[parameters: {'astreinte_id': 55, 'date_debut': datetime.datetime(2021, 12, 31, 16, 36, 9), 'date_fin': datetime.datetime(2022, 1, 3, 12, 8, 34)}]
(Background on this error at: https://sqlalche.me/e/14/e3q8)
 * Serving Flask app 'base' (lazy loading)
 * Environment: production
   WARNING: This is a development server. Do not use it in a production deployment.
   Use a production WSGI server instead.
 * Debug mode: on
Traceback (most recent call last):
  File "/Users/user/Documents/python/AstreinteFinale/base.py", line 417, in <module>
    app.run(debug=True, host="127.0.0.1",port=5000)
  File "/Users/user/Documents/python/AstreinteFinale/venv/lib/python3.10/site-packages/flask/app.py", line 920, in run
    run_simple(t.cast(str, host), port, self, **options)
  File "/Users/user/Documents/python/AstreinteFinale/venv/lib/python3.10/site-packages/werkzeug/serving.py", line 984, in run_simple
    s.bind(server_address)
OSError: [Errno 48] Address already in use
127.0.0.1 - - [03/Jan/2022 12:10:23] "GET /astreintes HTTP/1.1" 200 -
 * Serving Flask app 'base' (lazy loading)
 * Environment: production
   WARNING: This is a development server. Do not use it in a production deployment.
   Use a production WSGI server instead.
 * Debug mode: on
Traceback (most recent call last):
  File "/Users/user/Documents/python/AstreinteFinale/base.py", line 417, in <module>
    app.run(debug=True, host="127.0.0.1",port=5000)
  File "/Users/user/Documents/python/AstreinteFinale/venv/lib/python3.10/site-packages/flask/app.py", line 920, in run
    run_simple(t.cast(str, host), port, self, **options)
  File "/Users/user/Documents/python/AstreinteFinale/venv/lib/python3.10/site-packages/werkzeug/serving.py", line 984, in run_simple
    s.bind(server_address)
OSError: [Errno 48] Address already in use
 * Serving Flask app 'base' (lazy loading)
 * Environment: production
   WARNING: This is a development server. Do not use it in a production deployment.
   Use a production WSGI server instead.
 * Debug mode: on
Traceback (most recent call last):
  File "/Users/user/Documents/python/AstreinteFinale/base.py", line 417, in <module>
    app.run(debug=True, host="127.0.0.1",port=5000)
  File "/Users/user/Documents/python/AstreinteFinale/venv/lib/python3.10/site-packages/flask/app.py", line 920, in run
    run_simple(t.cast(str, host), port, self, **options)
  File "/Users/user/Documents/python/AstreinteFinale/venv/lib/python3.10/site-packages/werkzeug/serving.py", line 984, in run_simple
    s.bind(server_address)
OSError: [Errno 48] Address already in use
127.0.0.1 - - [03/Jan/2022 12:12:02] "[35m[1mGET /astreintes HTTP/1.1[0m" 500 -
Traceback (most recent call last):
  File "/Users/user/Documents/python/AstreinteFinale/venv/lib/python3.10/site-packages/sqlalchemy/engine/base.py", line 1802, in _execute_context
    self.dialect.do_execute(
  File "/Users/user/Documents/python/AstreinteFinale/venv/lib/python3.10/site-packages/sqlalchemy/engine/default.py", line 732, in do_execute
    cursor.execute(statement, parameters)
  File "/Users/user/Documents/python/AstreinteFinale/venv/lib/python3.10/site-packages/pymysql/cursors.py", line 148, in execute
    result = self._query(query)
  File "/Users/user/Documents/python/AstreinteFinale/venv/lib/python3.10/site-packages/pymysql/cursors.py", line 310, in _query
    conn.query(q)
  File "/Users/user/Documents/python/AstreinteFinale/venv/lib/python3.10/site-packages/pymysql/connections.py", line 548, in query
    self._affected_rows = self._read_query_result(unbuffered=unbuffered)
  File "/Users/user/Documents/python/AstreinteFinale/venv/lib/python3.10/site-packages/pymysql/connections.py", line 775, in _read_query_result
    result.read()
  File "/Users/user/Documents/python/AstreinteFinale/venv/lib/python3.10/site-packages/pymysql/connections.py", line 1156, in read
    first_packet = self.connection._read_packet()
  File "/Users/user/Documents/python/AstreinteFinale/venv/lib/python3.10/site-packages/pymysql/connections.py", line 725, in _read_packet
    packet.raise_for_error()
  File "/Users/user/Documents/python/AstreinteFinale/venv/lib/python3.10/site-packages/pymysql/protocol.py", line 221, in raise_for_error
    err.raise_mysql_exception(self._data)
  File "/Users/user/Documents/python/AstreinteFinale/venv/lib/python3.10/site-packages/pymysql/err.py", line 143, in raise_mysql_exception
    raise errorclass(errno, errval)
pymysql.err.OperationalError: (1364, "Field 'id' doesn't have a default value")

The above exception was the direct cause of the following exception:

Traceback (most recent call last):
  File "/Users/user/Documents/python/AstreinteFinale/venv/lib/python3.10/site-packages/flask/app.py", line 2091, in __call__
    return self.wsgi_app(environ, start_response)
  File "/Users/user/Documents/python/AstreinteFinale/venv/lib/python3.10/site-packages/flask/app.py", line 2076, in wsgi_app
    response = self.handle_exception(e)
  File "/Users/user/Documents/python/AstreinteFinale/venv/lib/python3.10/site-packages/flask/app.py", line 2073, in wsgi_app
    response = self.full_dispatch_request()
  File "/Users/user/Documents/python/AstreinteFinale/venv/lib/python3.10/site-packages/flask/app.py", line 1518, in full_dispatch_request
    rv = self.handle_user_exception(e)
  File "/Users/user/Documents/python/AstreinteFinale/venv/lib/python3.10/site-packages/flask/app.py", line 1516, in full_dispatch_request
    rv = self.dispatch_request()
  File "/Users/user/Documents/python/AstreinteFinale/venv/lib/python3.10/site-packages/flask/app.py", line 1502, in dispatch_request
    return self.ensure_sync(self.view_functions[rule.endpoint])(**req.view_args)
  File "/Users/user/Documents/python/AstreinteFinale/base.py", line 274, in send
    Commite(historique)
  File "/Users/user/Documents/python/AstreinteFinale/base.py", line 378, in Commite
    db.session.commit()
  File "<string>", line 2, in commit
    
  File "/Users/user/Documents/python/AstreinteFinale/venv/lib/python3.10/site-packages/sqlalchemy/orm/session.py", line 1431, in commit
    self._transaction.commit(_to_root=self.future)
  File "/Users/user/Documents/python/AstreinteFinale/venv/lib/python3.10/site-packages/sqlalchemy/orm/session.py", line 829, in commit
    self._prepare_impl()
  File "/Users/user/Documents/python/AstreinteFinale/venv/lib/python3.10/site-packages/sqlalchemy/orm/session.py", line 808, in _prepare_impl
    self.session.flush()
  File "/Users/user/Documents/python/AstreinteFinale/venv/lib/python3.10/site-packages/sqlalchemy/orm/session.py", line 3363, in flush
    self._flush(objects)
  File "/Users/user/Documents/python/AstreinteFinale/venv/lib/python3.10/site-packages/sqlalchemy/orm/session.py", line 3502, in _flush
    with util.safe_reraise():
  File "/Users/user/Documents/python/AstreinteFinale/venv/lib/python3.10/site-packages/sqlalchemy/util/langhelpers.py", line 70, in __exit__
    compat.raise_(
  File "/Users/user/Documents/python/AstreinteFinale/venv/lib/python3.10/site-packages/sqlalchemy/util/compat.py", line 207, in raise_
    raise exception
  File "/Users/user/Documents/python/AstreinteFinale/venv/lib/python3.10/site-packages/sqlalchemy/orm/session.py", line 3463, in _flush
    flush_context.execute()
  File "/Users/user/Documents/python/AstreinteFinale/venv/lib/python3.10/site-packages/sqlalchemy/orm/unitofwork.py", line 456, in execute
    rec.execute(self)
  File "/Users/user/Documents/python/AstreinteFinale/venv/lib/python3.10/site-packages/sqlalchemy/orm/unitofwork.py", line 630, in execute
    util.preloaded.orm_persistence.save_obj(
  File "/Users/user/Documents/python/AstreinteFinale/venv/lib/python3.10/site-packages/sqlalchemy/orm/persistence.py", line 244, in save_obj
    _emit_insert_statements(
  File "/Users/user/Documents/python/AstreinteFinale/venv/lib/python3.10/site-packages/sqlalchemy/orm/persistence.py", line 1221, in _emit_insert_statements
    result = connection._execute_20(
  File "/Users/user/Documents/python/AstreinteFinale/venv/lib/python3.10/site-packages/sqlalchemy/engine/base.py", line 1614, in _execute_20
    return meth(self, args_10style, kwargs_10style, execution_options)
  File "/Users/user/Documents/python/AstreinteFinale/venv/lib/python3.10/site-packages/sqlalchemy/sql/elements.py", line 325, in _execute_on_connection
    return connection._execute_clauseelement(
  File "/Users/user/Documents/python/AstreinteFinale/venv/lib/python3.10/site-packages/sqlalchemy/engine/base.py", line 1481, in _execute_clauseelement
    ret = self._execute_context(
  File "/Users/user/Documents/python/AstreinteFinale/venv/lib/python3.10/site-packages/sqlalchemy/engine/base.py", line 1845, in _execute_context
    self._handle_dbapi_exception(
  File "/Users/user/Documents/python/AstreinteFinale/venv/lib/python3.10/site-packages/sqlalchemy/engine/base.py", line 2026, in _handle_dbapi_exception
    util.raise_(
  File "/Users/user/Documents/python/AstreinteFinale/venv/lib/python3.10/site-packages/sqlalchemy/util/compat.py", line 207, in raise_
    raise exception
  File "/Users/user/Documents/python/AstreinteFinale/venv/lib/python3.10/site-packages/sqlalchemy/engine/base.py", line 1802, in _execute_context
    self.dialect.do_execute(
  File "/Users/user/Documents/python/AstreinteFinale/venv/lib/python3.10/site-packages/sqlalchemy/engine/default.py", line 732, in do_execute
    cursor.execute(statement, parameters)
  File "/Users/user/Documents/python/AstreinteFinale/venv/lib/python3.10/site-packages/pymysql/cursors.py", line 148, in execute
    result = self._query(query)
  File "/Users/user/Documents/python/AstreinteFinale/venv/lib/python3.10/site-packages/pymysql/cursors.py", line 310, in _query
    conn.query(q)
  File "/Users/user/Documents/python/AstreinteFinale/venv/lib/python3.10/site-packages/pymysql/connections.py", line 548, in query
    self._affected_rows = self._read_query_result(unbuffered=unbuffered)
  File "/Users/user/Documents/python/AstreinteFinale/venv/lib/python3.10/site-packages/pymysql/connections.py", line 775, in _read_query_result
    result.read()
  File "/Users/user/Documents/python/AstreinteFinale/venv/lib/python3.10/site-packages/pymysql/connections.py", line 1156, in read
    first_packet = self.connection._read_packet()
  File "/Users/user/Documents/python/AstreinteFinale/venv/lib/python3.10/site-packages/pymysql/connections.py", line 725, in _read_packet
    packet.raise_for_error()
  File "/Users/user/Documents/python/AstreinteFinale/venv/lib/python3.10/site-packages/pymysql/protocol.py", line 221, in raise_for_error
    err.raise_mysql_exception(self._data)
  File "/Users/user/Documents/python/AstreinteFinale/venv/lib/python3.10/site-packages/pymysql/err.py", line 143, in raise_mysql_exception
    raise errorclass(errno, errval)
sqlalchemy.exc.OperationalError: (pymysql.err.OperationalError) (1364, "Field 'id' doesn't have a default value")
[SQL: INSERT INTO historique (astreinte_id, date_debut, date_fin) VALUES (%(astreinte_id)s, %(date_debut)s, %(date_fin)s)]
[parameters: {'astreinte_id': 1, 'date_debut': datetime.datetime(2022, 1, 3, 12, 10, 10), 'date_fin': datetime.datetime(2022, 1, 3, 12, 12, 1)}]
(Background on this error at: https://sqlalche.me/e/14/e3q8)
 * Serving Flask app 'base' (lazy loading)
 * Environment: production
   WARNING: This is a development server. Do not use it in a production deployment.
   Use a production WSGI server instead.
 * Debug mode: on
Traceback (most recent call last):
  File "/Users/user/Documents/python/AstreinteFinale/base.py", line 417, in <module>
    app.run(debug=True, host="127.0.0.1",port=5000)
  File "/Users/user/Documents/python/AstreinteFinale/venv/lib/python3.10/site-packages/flask/app.py", line 920, in run
    run_simple(t.cast(str, host), port, self, **options)
  File "/Users/user/Documents/python/AstreinteFinale/venv/lib/python3.10/site-packages/werkzeug/serving.py", line 984, in run_simple
    s.bind(server_address)
OSError: [Errno 48] Address already in use
 * Serving Flask app 'base' (lazy loading)
 * Environment: production
   WARNING: This is a development server. Do not use it in a production deployment.
   Use a production WSGI server instead.
 * Debug mode: on
Traceback (most recent call last):
  File "/Users/user/Documents/python/AstreinteFinale/base.py", line 417, in <module>
    app.run(debug=True, host="127.0.0.1",port=5000)
  File "/Users/user/Documents/python/AstreinteFinale/venv/lib/python3.10/site-packages/flask/app.py", line 920, in run
    run_simple(t.cast(str, host), port, self, **options)
  File "/Users/user/Documents/python/AstreinteFinale/venv/lib/python3.10/site-packages/werkzeug/serving.py", line 984, in run_simple
    s.bind(server_address)
OSError: [Errno 48] Address already in use
127.0.0.1 - - [03/Jan/2022 12:14:05] "[35m[1mGET /astreintes HTTP/1.1[0m" 500 -
Traceback (most recent call last):
  File "/Users/user/Documents/python/AstreinteFinale/venv/lib/python3.10/site-packages/sqlalchemy/engine/base.py", line 1802, in _execute_context
    self.dialect.do_execute(
  File "/Users/user/Documents/python/AstreinteFinale/venv/lib/python3.10/site-packages/sqlalchemy/engine/default.py", line 732, in do_execute
    cursor.execute(statement, parameters)
  File "/Users/user/Documents/python/AstreinteFinale/venv/lib/python3.10/site-packages/pymysql/cursors.py", line 148, in execute
    result = self._query(query)
  File "/Users/user/Documents/python/AstreinteFinale/venv/lib/python3.10/site-packages/pymysql/cursors.py", line 310, in _query
    conn.query(q)
  File "/Users/user/Documents/python/AstreinteFinale/venv/lib/python3.10/site-packages/pymysql/connections.py", line 548, in query
    self._affected_rows = self._read_query_result(unbuffered=unbuffered)
  File "/Users/user/Documents/python/AstreinteFinale/venv/lib/python3.10/site-packages/pymysql/connections.py", line 775, in _read_query_result
    result.read()
  File "/Users/user/Documents/python/AstreinteFinale/venv/lib/python3.10/site-packages/pymysql/connections.py", line 1156, in read
    first_packet = self.connection._read_packet()
  File "/Users/user/Documents/python/AstreinteFinale/venv/lib/python3.10/site-packages/pymysql/connections.py", line 725, in _read_packet
    packet.raise_for_error()
  File "/Users/user/Documents/python/AstreinteFinale/venv/lib/python3.10/site-packages/pymysql/protocol.py", line 221, in raise_for_error
    err.raise_mysql_exception(self._data)
  File "/Users/user/Documents/python/AstreinteFinale/venv/lib/python3.10/site-packages/pymysql/err.py", line 143, in raise_mysql_exception
    raise errorclass(errno, errval)
pymysql.err.OperationalError: (1364, "Field 'id' doesn't have a default value")

The above exception was the direct cause of the following exception:

Traceback (most recent call last):
  File "/Users/user/Documents/python/AstreinteFinale/venv/lib/python3.10/site-packages/flask/app.py", line 2091, in __call__
    return self.wsgi_app(environ, start_response)
  File "/Users/user/Documents/python/AstreinteFinale/venv/lib/python3.10/site-packages/flask/app.py", line 2076, in wsgi_app
    response = self.handle_exception(e)
  File "/Users/user/Documents/python/AstreinteFinale/venv/lib/python3.10/site-packages/flask/app.py", line 2073, in wsgi_app
    response = self.full_dispatch_request()
  File "/Users/user/Documents/python/AstreinteFinale/venv/lib/python3.10/site-packages/flask/app.py", line 1518, in full_dispatch_request
    rv = self.handle_user_exception(e)
  File "/Users/user/Documents/python/AstreinteFinale/venv/lib/python3.10/site-packages/flask/app.py", line 1516, in full_dispatch_request
    rv = self.dispatch_request()
  File "/Users/user/Documents/python/AstreinteFinale/venv/lib/python3.10/site-packages/flask/app.py", line 1502, in dispatch_request
    return self.ensure_sync(self.view_functions[rule.endpoint])(**req.view_args)
  File "/Users/user/Documents/python/AstreinteFinale/base.py", line 274, in send
    Commite(historique)
  File "/Users/user/Documents/python/AstreinteFinale/base.py", line 378, in Commite
    db.session.commit()
  File "<string>", line 2, in commit
    
  File "/Users/user/Documents/python/AstreinteFinale/venv/lib/python3.10/site-packages/sqlalchemy/orm/session.py", line 1431, in commit
    self._transaction.commit(_to_root=self.future)
  File "/Users/user/Documents/python/AstreinteFinale/venv/lib/python3.10/site-packages/sqlalchemy/orm/session.py", line 829, in commit
    self._prepare_impl()
  File "/Users/user/Documents/python/AstreinteFinale/venv/lib/python3.10/site-packages/sqlalchemy/orm/session.py", line 808, in _prepare_impl
    self.session.flush()
  File "/Users/user/Documents/python/AstreinteFinale/venv/lib/python3.10/site-packages/sqlalchemy/orm/session.py", line 3363, in flush
    self._flush(objects)
  File "/Users/user/Documents/python/AstreinteFinale/venv/lib/python3.10/site-packages/sqlalchemy/orm/session.py", line 3502, in _flush
    with util.safe_reraise():
  File "/Users/user/Documents/python/AstreinteFinale/venv/lib/python3.10/site-packages/sqlalchemy/util/langhelpers.py", line 70, in __exit__
    compat.raise_(
  File "/Users/user/Documents/python/AstreinteFinale/venv/lib/python3.10/site-packages/sqlalchemy/util/compat.py", line 207, in raise_
    raise exception
  File "/Users/user/Documents/python/AstreinteFinale/venv/lib/python3.10/site-packages/sqlalchemy/orm/session.py", line 3463, in _flush
    flush_context.execute()
  File "/Users/user/Documents/python/AstreinteFinale/venv/lib/python3.10/site-packages/sqlalchemy/orm/unitofwork.py", line 456, in execute
    rec.execute(self)
  File "/Users/user/Documents/python/AstreinteFinale/venv/lib/python3.10/site-packages/sqlalchemy/orm/unitofwork.py", line 630, in execute
    util.preloaded.orm_persistence.save_obj(
  File "/Users/user/Documents/python/AstreinteFinale/venv/lib/python3.10/site-packages/sqlalchemy/orm/persistence.py", line 244, in save_obj
    _emit_insert_statements(
  File "/Users/user/Documents/python/AstreinteFinale/venv/lib/python3.10/site-packages/sqlalchemy/orm/persistence.py", line 1221, in _emit_insert_statements
    result = connection._execute_20(
  File "/Users/user/Documents/python/AstreinteFinale/venv/lib/python3.10/site-packages/sqlalchemy/engine/base.py", line 1614, in _execute_20
    return meth(self, args_10style, kwargs_10style, execution_options)
  File "/Users/user/Documents/python/AstreinteFinale/venv/lib/python3.10/site-packages/sqlalchemy/sql/elements.py", line 325, in _execute_on_connection
    return connection._execute_clauseelement(
  File "/Users/user/Documents/python/AstreinteFinale/venv/lib/python3.10/site-packages/sqlalchemy/engine/base.py", line 1481, in _execute_clauseelement
    ret = self._execute_context(
  File "/Users/user/Documents/python/AstreinteFinale/venv/lib/python3.10/site-packages/sqlalchemy/engine/base.py", line 1845, in _execute_context
    self._handle_dbapi_exception(
  File "/Users/user/Documents/python/AstreinteFinale/venv/lib/python3.10/site-packages/sqlalchemy/engine/base.py", line 2026, in _handle_dbapi_exception
    util.raise_(
  File "/Users/user/Documents/python/AstreinteFinale/venv/lib/python3.10/site-packages/sqlalchemy/util/compat.py", line 207, in raise_
    raise exception
  File "/Users/user/Documents/python/AstreinteFinale/venv/lib/python3.10/site-packages/sqlalchemy/engine/base.py", line 1802, in _execute_context
    self.dialect.do_execute(
  File "/Users/user/Documents/python/AstreinteFinale/venv/lib/python3.10/site-packages/sqlalchemy/engine/default.py", line 732, in do_execute
    cursor.execute(statement, parameters)
  File "/Users/user/Documents/python/AstreinteFinale/venv/lib/python3.10/site-packages/pymysql/cursors.py", line 148, in execute
    result = self._query(query)
  File "/Users/user/Documents/python/AstreinteFinale/venv/lib/python3.10/site-packages/pymysql/cursors.py", line 310, in _query
    conn.query(q)
  File "/Users/user/Documents/python/AstreinteFinale/venv/lib/python3.10/site-packages/pymysql/connections.py", line 548, in query
    self._affected_rows = self._read_query_result(unbuffered=unbuffered)
  File "/Users/user/Documents/python/AstreinteFinale/venv/lib/python3.10/site-packages/pymysql/connections.py", line 775, in _read_query_result
    result.read()
  File "/Users/user/Documents/python/AstreinteFinale/venv/lib/python3.10/site-packages/pymysql/connections.py", line 1156, in read
    first_packet = self.connection._read_packet()
  File "/Users/user/Documents/python/AstreinteFinale/venv/lib/python3.10/site-packages/pymysql/connections.py", line 725, in _read_packet
    packet.raise_for_error()
  File "/Users/user/Documents/python/AstreinteFinale/venv/lib/python3.10/site-packages/pymysql/protocol.py", line 221, in raise_for_error
    err.raise_mysql_exception(self._data)
  File "/Users/user/Documents/python/AstreinteFinale/venv/lib/python3.10/site-packages/pymysql/err.py", line 143, in raise_mysql_exception
    raise errorclass(errno, errval)
sqlalchemy.exc.OperationalError: (pymysql.err.OperationalError) (1364, "Field 'id' doesn't have a default value")
[SQL: INSERT INTO historique (astreinte_id, date_debut, date_fin) VALUES (%(astreinte_id)s, %(date_debut)s, %(date_fin)s)]
[parameters: {'astreinte_id': 1, 'date_debut': datetime.datetime(2022, 1, 3, 12, 10, 10), 'date_fin': datetime.datetime(2022, 1, 3, 12, 14, 4)}]
(Background on this error at: https://sqlalche.me/e/14/e3q8)
 * Serving Flask app 'base' (lazy loading)
 * Environment: production
   WARNING: This is a development server. Do not use it in a production deployment.
   Use a production WSGI server instead.
 * Debug mode: on
Traceback (most recent call last):
  File "/Users/user/Documents/python/AstreinteFinale/base.py", line 417, in <module>
    app.run(debug=True, host="127.0.0.1",port=5000)
  File "/Users/user/Documents/python/AstreinteFinale/venv/lib/python3.10/site-packages/flask/app.py", line 920, in run
    run_simple(t.cast(str, host), port, self, **options)
  File "/Users/user/Documents/python/AstreinteFinale/venv/lib/python3.10/site-packages/werkzeug/serving.py", line 984, in run_simple
    s.bind(server_address)
OSError: [Errno 48] Address already in use
 * Serving Flask app 'base' (lazy loading)
 * Environment: production
   WARNING: This is a development server. Do not use it in a production deployment.
   Use a production WSGI server instead.
 * Debug mode: on
Traceback (most recent call last):
  File "/Users/user/Documents/python/AstreinteFinale/base.py", line 417, in <module>
    app.run(debug=True, host="127.0.0.1",port=5000)
  File "/Users/user/Documents/python/AstreinteFinale/venv/lib/python3.10/site-packages/flask/app.py", line 920, in run
    run_simple(t.cast(str, host), port, self, **options)
  File "/Users/user/Documents/python/AstreinteFinale/venv/lib/python3.10/site-packages/werkzeug/serving.py", line 984, in run_simple
    s.bind(server_address)
OSError: [Errno 48] Address already in use
127.0.0.1 - - [03/Jan/2022 12:16:06] "[35m[1mGET /astreintes HTTP/1.1[0m" 500 -
Traceback (most recent call last):
  File "/Users/user/Documents/python/AstreinteFinale/venv/lib/python3.10/site-packages/sqlalchemy/engine/base.py", line 1802, in _execute_context
    self.dialect.do_execute(
  File "/Users/user/Documents/python/AstreinteFinale/venv/lib/python3.10/site-packages/sqlalchemy/engine/default.py", line 732, in do_execute
    cursor.execute(statement, parameters)
  File "/Users/user/Documents/python/AstreinteFinale/venv/lib/python3.10/site-packages/pymysql/cursors.py", line 148, in execute
    result = self._query(query)
  File "/Users/user/Documents/python/AstreinteFinale/venv/lib/python3.10/site-packages/pymysql/cursors.py", line 310, in _query
    conn.query(q)
  File "/Users/user/Documents/python/AstreinteFinale/venv/lib/python3.10/site-packages/pymysql/connections.py", line 548, in query
    self._affected_rows = self._read_query_result(unbuffered=unbuffered)
  File "/Users/user/Documents/python/AstreinteFinale/venv/lib/python3.10/site-packages/pymysql/connections.py", line 775, in _read_query_result
    result.read()
  File "/Users/user/Documents/python/AstreinteFinale/venv/lib/python3.10/site-packages/pymysql/connections.py", line 1156, in read
    first_packet = self.connection._read_packet()
  File "/Users/user/Documents/python/AstreinteFinale/venv/lib/python3.10/site-packages/pymysql/connections.py", line 725, in _read_packet
    packet.raise_for_error()
  File "/Users/user/Documents/python/AstreinteFinale/venv/lib/python3.10/site-packages/pymysql/protocol.py", line 221, in raise_for_error
    err.raise_mysql_exception(self._data)
  File "/Users/user/Documents/python/AstreinteFinale/venv/lib/python3.10/site-packages/pymysql/err.py", line 143, in raise_mysql_exception
    raise errorclass(errno, errval)
pymysql.err.OperationalError: (1364, "Field 'id' doesn't have a default value")

The above exception was the direct cause of the following exception:

Traceback (most recent call last):
  File "/Users/user/Documents/python/AstreinteFinale/venv/lib/python3.10/site-packages/flask/app.py", line 2091, in __call__
    return self.wsgi_app(environ, start_response)
  File "/Users/user/Documents/python/AstreinteFinale/venv/lib/python3.10/site-packages/flask/app.py", line 2076, in wsgi_app
    response = self.handle_exception(e)
  File "/Users/user/Documents/python/AstreinteFinale/venv/lib/python3.10/site-packages/flask/app.py", line 2073, in wsgi_app
    response = self.full_dispatch_request()
  File "/Users/user/Documents/python/AstreinteFinale/venv/lib/python3.10/site-packages/flask/app.py", line 1518, in full_dispatch_request
    rv = self.handle_user_exception(e)
  File "/Users/user/Documents/python/AstreinteFinale/venv/lib/python3.10/site-packages/flask/app.py", line 1516, in full_dispatch_request
    rv = self.dispatch_request()
  File "/Users/user/Documents/python/AstreinteFinale/venv/lib/python3.10/site-packages/flask/app.py", line 1502, in dispatch_request
    return self.ensure_sync(self.view_functions[rule.endpoint])(**req.view_args)
  File "/Users/user/Documents/python/AstreinteFinale/base.py", line 274, in send
    Commite(historique)
  File "/Users/user/Documents/python/AstreinteFinale/base.py", line 378, in Commite
    db.session.commit()
  File "<string>", line 2, in commit
    
  File "/Users/user/Documents/python/AstreinteFinale/venv/lib/python3.10/site-packages/sqlalchemy/orm/session.py", line 1431, in commit
    self._transaction.commit(_to_root=self.future)
  File "/Users/user/Documents/python/AstreinteFinale/venv/lib/python3.10/site-packages/sqlalchemy/orm/session.py", line 829, in commit
    self._prepare_impl()
  File "/Users/user/Documents/python/AstreinteFinale/venv/lib/python3.10/site-packages/sqlalchemy/orm/session.py", line 808, in _prepare_impl
    self.session.flush()
  File "/Users/user/Documents/python/AstreinteFinale/venv/lib/python3.10/site-packages/sqlalchemy/orm/session.py", line 3363, in flush
    self._flush(objects)
  File "/Users/user/Documents/python/AstreinteFinale/venv/lib/python3.10/site-packages/sqlalchemy/orm/session.py", line 3502, in _flush
    with util.safe_reraise():
  File "/Users/user/Documents/python/AstreinteFinale/venv/lib/python3.10/site-packages/sqlalchemy/util/langhelpers.py", line 70, in __exit__
    compat.raise_(
  File "/Users/user/Documents/python/AstreinteFinale/venv/lib/python3.10/site-packages/sqlalchemy/util/compat.py", line 207, in raise_
    raise exception
  File "/Users/user/Documents/python/AstreinteFinale/venv/lib/python3.10/site-packages/sqlalchemy/orm/session.py", line 3463, in _flush
    flush_context.execute()
  File "/Users/user/Documents/python/AstreinteFinale/venv/lib/python3.10/site-packages/sqlalchemy/orm/unitofwork.py", line 456, in execute
    rec.execute(self)
  File "/Users/user/Documents/python/AstreinteFinale/venv/lib/python3.10/site-packages/sqlalchemy/orm/unitofwork.py", line 630, in execute
    util.preloaded.orm_persistence.save_obj(
  File "/Users/user/Documents/python/AstreinteFinale/venv/lib/python3.10/site-packages/sqlalchemy/orm/persistence.py", line 244, in save_obj
    _emit_insert_statements(
  File "/Users/user/Documents/python/AstreinteFinale/venv/lib/python3.10/site-packages/sqlalchemy/orm/persistence.py", line 1221, in _emit_insert_statements
    result = connection._execute_20(
  File "/Users/user/Documents/python/AstreinteFinale/venv/lib/python3.10/site-packages/sqlalchemy/engine/base.py", line 1614, in _execute_20
    return meth(self, args_10style, kwargs_10style, execution_options)
  File "/Users/user/Documents/python/AstreinteFinale/venv/lib/python3.10/site-packages/sqlalchemy/sql/elements.py", line 325, in _execute_on_connection
    return connection._execute_clauseelement(
  File "/Users/user/Documents/python/AstreinteFinale/venv/lib/python3.10/site-packages/sqlalchemy/engine/base.py", line 1481, in _execute_clauseelement
    ret = self._execute_context(
  File "/Users/user/Documents/python/AstreinteFinale/venv/lib/python3.10/site-packages/sqlalchemy/engine/base.py", line 1845, in _execute_context
    self._handle_dbapi_exception(
  File "/Users/user/Documents/python/AstreinteFinale/venv/lib/python3.10/site-packages/sqlalchemy/engine/base.py", line 2026, in _handle_dbapi_exception
    util.raise_(
  File "/Users/user/Documents/python/AstreinteFinale/venv/lib/python3.10/site-packages/sqlalchemy/util/compat.py", line 207, in raise_
    raise exception
  File "/Users/user/Documents/python/AstreinteFinale/venv/lib/python3.10/site-packages/sqlalchemy/engine/base.py", line 1802, in _execute_context
    self.dialect.do_execute(
  File "/Users/user/Documents/python/AstreinteFinale/venv/lib/python3.10/site-packages/sqlalchemy/engine/default.py", line 732, in do_execute
    cursor.execute(statement, parameters)
  File "/Users/user/Documents/python/AstreinteFinale/venv/lib/python3.10/site-packages/pymysql/cursors.py", line 148, in execute
    result = self._query(query)
  File "/Users/user/Documents/python/AstreinteFinale/venv/lib/python3.10/site-packages/pymysql/cursors.py", line 310, in _query
    conn.query(q)
  File "/Users/user/Documents/python/AstreinteFinale/venv/lib/python3.10/site-packages/pymysql/connections.py", line 548, in query
    self._affected_rows = self._read_query_result(unbuffered=unbuffered)
  File "/Users/user/Documents/python/AstreinteFinale/venv/lib/python3.10/site-packages/pymysql/connections.py", line 775, in _read_query_result
    result.read()
  File "/Users/user/Documents/python/AstreinteFinale/venv/lib/python3.10/site-packages/pymysql/connections.py", line 1156, in read
    first_packet = self.connection._read_packet()
  File "/Users/user/Documents/python/AstreinteFinale/venv/lib/python3.10/site-packages/pymysql/connections.py", line 725, in _read_packet
    packet.raise_for_error()
  File "/Users/user/Documents/python/AstreinteFinale/venv/lib/python3.10/site-packages/pymysql/protocol.py", line 221, in raise_for_error
    err.raise_mysql_exception(self._data)
  File "/Users/user/Documents/python/AstreinteFinale/venv/lib/python3.10/site-packages/pymysql/err.py", line 143, in raise_mysql_exception
    raise errorclass(errno, errval)
sqlalchemy.exc.OperationalError: (pymysql.err.OperationalError) (1364, "Field 'id' doesn't have a default value")
[SQL: INSERT INTO historique (astreinte_id, date_debut, date_fin) VALUES (%(astreinte_id)s, %(date_debut)s, %(date_fin)s)]
[parameters: {'astreinte_id': 1, 'date_debut': datetime.datetime(2022, 1, 3, 12, 10, 10), 'date_fin': datetime.datetime(2022, 1, 3, 12, 16, 4)}]
(Background on this error at: https://sqlalche.me/e/14/e3q8)
 * Detected change in '/Users/user/Documents/python/AstreinteFinale/base.py', reloading
 * Detected change in '/Users/user/Documents/python/AstreinteFinale/base.py', reloading
 * Restarting with stat
 * Restarting with stat
 * Serving Flask app 'base' (lazy loading)
 * Environment: production
   WARNING: This is a development server. Do not use it in a production deployment.
   Use a production WSGI server instead.
 * Debug mode: on
 * Debugger is active!
 * Debugger is active!
 * Debugger PIN: 655-285-932
 * Debugger PIN: 655-285-932
Traceback (most recent call last):
  File "/Users/user/Documents/python/AstreinteFinale/base.py", line 417, in <module>
    app.run(debug=True, host="127.0.0.1",port=500)
  File "/Users/user/Documents/python/AstreinteFinale/venv/lib/python3.10/site-packages/flask/app.py", line 920, in run
    run_simple(t.cast(str, host), port, self, **options)
  File "/Users/user/Documents/python/AstreinteFinale/venv/lib/python3.10/site-packages/werkzeug/serving.py", line 984, in run_simple
    s.bind(server_address)
OSError: [Errno 48] Address already in use
 * Serving Flask app 'base' (lazy loading)
 * Environment: production
   WARNING: This is a development server. Do not use it in a production deployment.
   Use a production WSGI server instead.
 * Debug mode: on
Traceback (most recent call last):
  File "/Users/user/Documents/python/AstreinteFinale/base.py", line 417, in <module>
    app.run(debug=True, host="127.0.0.1",port=500)
  File "/Users/user/Documents/python/AstreinteFinale/venv/lib/python3.10/site-packages/flask/app.py", line 920, in run
    run_simple(t.cast(str, host), port, self, **options)
  File "/Users/user/Documents/python/AstreinteFinale/venv/lib/python3.10/site-packages/werkzeug/serving.py", line 984, in run_simple
    s.bind(server_address)
PermissionError: [Errno 13] Permission denied
127.0.0.1 - - [03/Jan/2022 12:18:04] "[35m[1mGET /astreintes HTTP/1.1[0m" 500 -
Traceback (most recent call last):
  File "/Users/user/Documents/python/AstreinteFinale/venv/lib/python3.10/site-packages/sqlalchemy/engine/base.py", line 1802, in _execute_context
    self.dialect.do_execute(
  File "/Users/user/Documents/python/AstreinteFinale/venv/lib/python3.10/site-packages/sqlalchemy/engine/default.py", line 732, in do_execute
    cursor.execute(statement, parameters)
  File "/Users/user/Documents/python/AstreinteFinale/venv/lib/python3.10/site-packages/pymysql/cursors.py", line 148, in execute
    result = self._query(query)
  File "/Users/user/Documents/python/AstreinteFinale/venv/lib/python3.10/site-packages/pymysql/cursors.py", line 310, in _query
    conn.query(q)
  File "/Users/user/Documents/python/AstreinteFinale/venv/lib/python3.10/site-packages/pymysql/connections.py", line 548, in query
    self._affected_rows = self._read_query_result(unbuffered=unbuffered)
  File "/Users/user/Documents/python/AstreinteFinale/venv/lib/python3.10/site-packages/pymysql/connections.py", line 775, in _read_query_result
    result.read()
  File "/Users/user/Documents/python/AstreinteFinale/venv/lib/python3.10/site-packages/pymysql/connections.py", line 1156, in read
    first_packet = self.connection._read_packet()
  File "/Users/user/Documents/python/AstreinteFinale/venv/lib/python3.10/site-packages/pymysql/connections.py", line 725, in _read_packet
    packet.raise_for_error()
  File "/Users/user/Documents/python/AstreinteFinale/venv/lib/python3.10/site-packages/pymysql/protocol.py", line 221, in raise_for_error
    err.raise_mysql_exception(self._data)
  File "/Users/user/Documents/python/AstreinteFinale/venv/lib/python3.10/site-packages/pymysql/err.py", line 143, in raise_mysql_exception
    raise errorclass(errno, errval)
pymysql.err.OperationalError: (1364, "Field 'id' doesn't have a default value")

The above exception was the direct cause of the following exception:

Traceback (most recent call last):
  File "/Users/user/Documents/python/AstreinteFinale/venv/lib/python3.10/site-packages/flask/app.py", line 2091, in __call__
    return self.wsgi_app(environ, start_response)
  File "/Users/user/Documents/python/AstreinteFinale/venv/lib/python3.10/site-packages/flask/app.py", line 2076, in wsgi_app
    response = self.handle_exception(e)
  File "/Users/user/Documents/python/AstreinteFinale/venv/lib/python3.10/site-packages/flask/app.py", line 2073, in wsgi_app
    response = self.full_dispatch_request()
  File "/Users/user/Documents/python/AstreinteFinale/venv/lib/python3.10/site-packages/flask/app.py", line 1518, in full_dispatch_request
    rv = self.handle_user_exception(e)
  File "/Users/user/Documents/python/AstreinteFinale/venv/lib/python3.10/site-packages/flask/app.py", line 1516, in full_dispatch_request
    rv = self.dispatch_request()
  File "/Users/user/Documents/python/AstreinteFinale/venv/lib/python3.10/site-packages/flask/app.py", line 1502, in dispatch_request
    return self.ensure_sync(self.view_functions[rule.endpoint])(**req.view_args)
  File "/Users/user/Documents/python/AstreinteFinale/base.py", line 274, in send
    Commite(historique)
  File "/Users/user/Documents/python/AstreinteFinale/base.py", line 378, in Commite
    db.session.commit()
  File "<string>", line 2, in commit
    
  File "/Users/user/Documents/python/AstreinteFinale/venv/lib/python3.10/site-packages/sqlalchemy/orm/session.py", line 1431, in commit
    self._transaction.commit(_to_root=self.future)
  File "/Users/user/Documents/python/AstreinteFinale/venv/lib/python3.10/site-packages/sqlalchemy/orm/session.py", line 829, in commit
    self._prepare_impl()
  File "/Users/user/Documents/python/AstreinteFinale/venv/lib/python3.10/site-packages/sqlalchemy/orm/session.py", line 808, in _prepare_impl
    self.session.flush()
  File "/Users/user/Documents/python/AstreinteFinale/venv/lib/python3.10/site-packages/sqlalchemy/orm/session.py", line 3363, in flush
    self._flush(objects)
  File "/Users/user/Documents/python/AstreinteFinale/venv/lib/python3.10/site-packages/sqlalchemy/orm/session.py", line 3502, in _flush
    with util.safe_reraise():
  File "/Users/user/Documents/python/AstreinteFinale/venv/lib/python3.10/site-packages/sqlalchemy/util/langhelpers.py", line 70, in __exit__
    compat.raise_(
  File "/Users/user/Documents/python/AstreinteFinale/venv/lib/python3.10/site-packages/sqlalchemy/util/compat.py", line 207, in raise_
    raise exception
  File "/Users/user/Documents/python/AstreinteFinale/venv/lib/python3.10/site-packages/sqlalchemy/orm/session.py", line 3463, in _flush
    flush_context.execute()
  File "/Users/user/Documents/python/AstreinteFinale/venv/lib/python3.10/site-packages/sqlalchemy/orm/unitofwork.py", line 456, in execute
    rec.execute(self)
  File "/Users/user/Documents/python/AstreinteFinale/venv/lib/python3.10/site-packages/sqlalchemy/orm/unitofwork.py", line 630, in execute
    util.preloaded.orm_persistence.save_obj(
  File "/Users/user/Documents/python/AstreinteFinale/venv/lib/python3.10/site-packages/sqlalchemy/orm/persistence.py", line 244, in save_obj
    _emit_insert_statements(
  File "/Users/user/Documents/python/AstreinteFinale/venv/lib/python3.10/site-packages/sqlalchemy/orm/persistence.py", line 1221, in _emit_insert_statements
    result = connection._execute_20(
  File "/Users/user/Documents/python/AstreinteFinale/venv/lib/python3.10/site-packages/sqlalchemy/engine/base.py", line 1614, in _execute_20
    return meth(self, args_10style, kwargs_10style, execution_options)
  File "/Users/user/Documents/python/AstreinteFinale/venv/lib/python3.10/site-packages/sqlalchemy/sql/elements.py", line 325, in _execute_on_connection
    return connection._execute_clauseelement(
  File "/Users/user/Documents/python/AstreinteFinale/venv/lib/python3.10/site-packages/sqlalchemy/engine/base.py", line 1481, in _execute_clauseelement
    ret = self._execute_context(
  File "/Users/user/Documents/python/AstreinteFinale/venv/lib/python3.10/site-packages/sqlalchemy/engine/base.py", line 1845, in _execute_context
    self._handle_dbapi_exception(
  File "/Users/user/Documents/python/AstreinteFinale/venv/lib/python3.10/site-packages/sqlalchemy/engine/base.py", line 2026, in _handle_dbapi_exception
    util.raise_(
  File "/Users/user/Documents/python/AstreinteFinale/venv/lib/python3.10/site-packages/sqlalchemy/util/compat.py", line 207, in raise_
    raise exception
  File "/Users/user/Documents/python/AstreinteFinale/venv/lib/python3.10/site-packages/sqlalchemy/engine/base.py", line 1802, in _execute_context
    self.dialect.do_execute(
  File "/Users/user/Documents/python/AstreinteFinale/venv/lib/python3.10/site-packages/sqlalchemy/engine/default.py", line 732, in do_execute
    cursor.execute(statement, parameters)
  File "/Users/user/Documents/python/AstreinteFinale/venv/lib/python3.10/site-packages/pymysql/cursors.py", line 148, in execute
    result = self._query(query)
  File "/Users/user/Documents/python/AstreinteFinale/venv/lib/python3.10/site-packages/pymysql/cursors.py", line 310, in _query
    conn.query(q)
  File "/Users/user/Documents/python/AstreinteFinale/venv/lib/python3.10/site-packages/pymysql/connections.py", line 548, in query
    self._affected_rows = self._read_query_result(unbuffered=unbuffered)
  File "/Users/user/Documents/python/AstreinteFinale/venv/lib/python3.10/site-packages/pymysql/connections.py", line 775, in _read_query_result
    result.read()
  File "/Users/user/Documents/python/AstreinteFinale/venv/lib/python3.10/site-packages/pymysql/connections.py", line 1156, in read
    first_packet = self.connection._read_packet()
  File "/Users/user/Documents/python/AstreinteFinale/venv/lib/python3.10/site-packages/pymysql/connections.py", line 725, in _read_packet
    packet.raise_for_error()
  File "/Users/user/Documents/python/AstreinteFinale/venv/lib/python3.10/site-packages/pymysql/protocol.py", line 221, in raise_for_error
    err.raise_mysql_exception(self._data)
  File "/Users/user/Documents/python/AstreinteFinale/venv/lib/python3.10/site-packages/pymysql/err.py", line 143, in raise_mysql_exception
    raise errorclass(errno, errval)
sqlalchemy.exc.OperationalError: (pymysql.err.OperationalError) (1364, "Field 'id' doesn't have a default value")
[SQL: INSERT INTO historique (astreinte_id, date_debut, date_fin) VALUES (%(astreinte_id)s, %(date_debut)s, %(date_fin)s)]
[parameters: {'astreinte_id': 1, 'date_debut': datetime.datetime(2022, 1, 3, 12, 10, 10), 'date_fin': datetime.datetime(2022, 1, 3, 12, 18, 3)}]
(Background on this error at: https://sqlalche.me/e/14/e3q8)
 * Serving Flask app 'base' (lazy loading)
 * Environment: production
   WARNING: This is a development server. Do not use it in a production deployment.
   Use a production WSGI server instead.
 * Debug mode: on
Traceback (most recent call last):
  File "/Users/user/Documents/python/AstreinteFinale/base.py", line 417, in <module>
    app.run(debug=True, host="127.0.0.1",port=500)
  File "/Users/user/Documents/python/AstreinteFinale/venv/lib/python3.10/site-packages/flask/app.py", line 920, in run
    run_simple(t.cast(str, host), port, self, **options)
  File "/Users/user/Documents/python/AstreinteFinale/venv/lib/python3.10/site-packages/werkzeug/serving.py", line 984, in run_simple
    s.bind(server_address)
PermissionError: [Errno 13] Permission denied
 * Serving Flask app 'base' (lazy loading)
 * Environment: production
   WARNING: This is a development server. Do not use it in a production deployment.
   Use a production WSGI server instead.
 * Debug mode: on
Traceback (most recent call last):
  File "/Users/user/Documents/python/AstreinteFinale/base.py", line 417, in <module>
    app.run(debug=True, host="127.0.0.1",port=500)
  File "/Users/user/Documents/python/AstreinteFinale/venv/lib/python3.10/site-packages/flask/app.py", line 920, in run
    run_simple(t.cast(str, host), port, self, **options)
  File "/Users/user/Documents/python/AstreinteFinale/venv/lib/python3.10/site-packages/werkzeug/serving.py", line 984, in run_simple
    s.bind(server_address)
PermissionError: [Errno 13] Permission denied
127.0.0.1 - - [03/Jan/2022 12:20:04] "[35m[1mGET /astreintes HTTP/1.1[0m" 500 -
Traceback (most recent call last):
  File "/Users/user/Documents/python/AstreinteFinale/venv/lib/python3.10/site-packages/sqlalchemy/engine/base.py", line 1802, in _execute_context
    self.dialect.do_execute(
  File "/Users/user/Documents/python/AstreinteFinale/venv/lib/python3.10/site-packages/sqlalchemy/engine/default.py", line 732, in do_execute
    cursor.execute(statement, parameters)
  File "/Users/user/Documents/python/AstreinteFinale/venv/lib/python3.10/site-packages/pymysql/cursors.py", line 148, in execute
    result = self._query(query)
  File "/Users/user/Documents/python/AstreinteFinale/venv/lib/python3.10/site-packages/pymysql/cursors.py", line 310, in _query
    conn.query(q)
  File "/Users/user/Documents/python/AstreinteFinale/venv/lib/python3.10/site-packages/pymysql/connections.py", line 548, in query
    self._affected_rows = self._read_query_result(unbuffered=unbuffered)
  File "/Users/user/Documents/python/AstreinteFinale/venv/lib/python3.10/site-packages/pymysql/connections.py", line 775, in _read_query_result
    result.read()
  File "/Users/user/Documents/python/AstreinteFinale/venv/lib/python3.10/site-packages/pymysql/connections.py", line 1156, in read
    first_packet = self.connection._read_packet()
  File "/Users/user/Documents/python/AstreinteFinale/venv/lib/python3.10/site-packages/pymysql/connections.py", line 725, in _read_packet
    packet.raise_for_error()
  File "/Users/user/Documents/python/AstreinteFinale/venv/lib/python3.10/site-packages/pymysql/protocol.py", line 221, in raise_for_error
    err.raise_mysql_exception(self._data)
  File "/Users/user/Documents/python/AstreinteFinale/venv/lib/python3.10/site-packages/pymysql/err.py", line 143, in raise_mysql_exception
    raise errorclass(errno, errval)
pymysql.err.OperationalError: (1364, "Field 'id' doesn't have a default value")

The above exception was the direct cause of the following exception:

Traceback (most recent call last):
  File "/Users/user/Documents/python/AstreinteFinale/venv/lib/python3.10/site-packages/flask/app.py", line 2091, in __call__
    return self.wsgi_app(environ, start_response)
  File "/Users/user/Documents/python/AstreinteFinale/venv/lib/python3.10/site-packages/flask/app.py", line 2076, in wsgi_app
    response = self.handle_exception(e)
  File "/Users/user/Documents/python/AstreinteFinale/venv/lib/python3.10/site-packages/flask/app.py", line 2073, in wsgi_app
    response = self.full_dispatch_request()
  File "/Users/user/Documents/python/AstreinteFinale/venv/lib/python3.10/site-packages/flask/app.py", line 1518, in full_dispatch_request
    rv = self.handle_user_exception(e)
  File "/Users/user/Documents/python/AstreinteFinale/venv/lib/python3.10/site-packages/flask/app.py", line 1516, in full_dispatch_request
    rv = self.dispatch_request()
  File "/Users/user/Documents/python/AstreinteFinale/venv/lib/python3.10/site-packages/flask/app.py", line 1502, in dispatch_request
    return self.ensure_sync(self.view_functions[rule.endpoint])(**req.view_args)
  File "/Users/user/Documents/python/AstreinteFinale/base.py", line 274, in send
    Commite(historique)
  File "/Users/user/Documents/python/AstreinteFinale/base.py", line 378, in Commite
    db.session.commit()
  File "<string>", line 2, in commit
    
  File "/Users/user/Documents/python/AstreinteFinale/venv/lib/python3.10/site-packages/sqlalchemy/orm/session.py", line 1431, in commit
    self._transaction.commit(_to_root=self.future)
  File "/Users/user/Documents/python/AstreinteFinale/venv/lib/python3.10/site-packages/sqlalchemy/orm/session.py", line 829, in commit
    self._prepare_impl()
  File "/Users/user/Documents/python/AstreinteFinale/venv/lib/python3.10/site-packages/sqlalchemy/orm/session.py", line 808, in _prepare_impl
    self.session.flush()
  File "/Users/user/Documents/python/AstreinteFinale/venv/lib/python3.10/site-packages/sqlalchemy/orm/session.py", line 3363, in flush
    self._flush(objects)
  File "/Users/user/Documents/python/AstreinteFinale/venv/lib/python3.10/site-packages/sqlalchemy/orm/session.py", line 3502, in _flush
    with util.safe_reraise():
  File "/Users/user/Documents/python/AstreinteFinale/venv/lib/python3.10/site-packages/sqlalchemy/util/langhelpers.py", line 70, in __exit__
    compat.raise_(
  File "/Users/user/Documents/python/AstreinteFinale/venv/lib/python3.10/site-packages/sqlalchemy/util/compat.py", line 207, in raise_
    raise exception
  File "/Users/user/Documents/python/AstreinteFinale/venv/lib/python3.10/site-packages/sqlalchemy/orm/session.py", line 3463, in _flush
    flush_context.execute()
  File "/Users/user/Documents/python/AstreinteFinale/venv/lib/python3.10/site-packages/sqlalchemy/orm/unitofwork.py", line 456, in execute
    rec.execute(self)
  File "/Users/user/Documents/python/AstreinteFinale/venv/lib/python3.10/site-packages/sqlalchemy/orm/unitofwork.py", line 630, in execute
    util.preloaded.orm_persistence.save_obj(
  File "/Users/user/Documents/python/AstreinteFinale/venv/lib/python3.10/site-packages/sqlalchemy/orm/persistence.py", line 244, in save_obj
    _emit_insert_statements(
  File "/Users/user/Documents/python/AstreinteFinale/venv/lib/python3.10/site-packages/sqlalchemy/orm/persistence.py", line 1221, in _emit_insert_statements
    result = connection._execute_20(
  File "/Users/user/Documents/python/AstreinteFinale/venv/lib/python3.10/site-packages/sqlalchemy/engine/base.py", line 1614, in _execute_20
    return meth(self, args_10style, kwargs_10style, execution_options)
  File "/Users/user/Documents/python/AstreinteFinale/venv/lib/python3.10/site-packages/sqlalchemy/sql/elements.py", line 325, in _execute_on_connection
    return connection._execute_clauseelement(
  File "/Users/user/Documents/python/AstreinteFinale/venv/lib/python3.10/site-packages/sqlalchemy/engine/base.py", line 1481, in _execute_clauseelement
    ret = self._execute_context(
  File "/Users/user/Documents/python/AstreinteFinale/venv/lib/python3.10/site-packages/sqlalchemy/engine/base.py", line 1845, in _execute_context
    self._handle_dbapi_exception(
  File "/Users/user/Documents/python/AstreinteFinale/venv/lib/python3.10/site-packages/sqlalchemy/engine/base.py", line 2026, in _handle_dbapi_exception
    util.raise_(
  File "/Users/user/Documents/python/AstreinteFinale/venv/lib/python3.10/site-packages/sqlalchemy/util/compat.py", line 207, in raise_
    raise exception
  File "/Users/user/Documents/python/AstreinteFinale/venv/lib/python3.10/site-packages/sqlalchemy/engine/base.py", line 1802, in _execute_context
    self.dialect.do_execute(
  File "/Users/user/Documents/python/AstreinteFinale/venv/lib/python3.10/site-packages/sqlalchemy/engine/default.py", line 732, in do_execute
    cursor.execute(statement, parameters)
  File "/Users/user/Documents/python/AstreinteFinale/venv/lib/python3.10/site-packages/pymysql/cursors.py", line 148, in execute
    result = self._query(query)
  File "/Users/user/Documents/python/AstreinteFinale/venv/lib/python3.10/site-packages/pymysql/cursors.py", line 310, in _query
    conn.query(q)
  File "/Users/user/Documents/python/AstreinteFinale/venv/lib/python3.10/site-packages/pymysql/connections.py", line 548, in query
    self._affected_rows = self._read_query_result(unbuffered=unbuffered)
  File "/Users/user/Documents/python/AstreinteFinale/venv/lib/python3.10/site-packages/pymysql/connections.py", line 775, in _read_query_result
    result.read()
  File "/Users/user/Documents/python/AstreinteFinale/venv/lib/python3.10/site-packages/pymysql/connections.py", line 1156, in read
    first_packet = self.connection._read_packet()
  File "/Users/user/Documents/python/AstreinteFinale/venv/lib/python3.10/site-packages/pymysql/connections.py", line 725, in _read_packet
    packet.raise_for_error()
  File "/Users/user/Documents/python/AstreinteFinale/venv/lib/python3.10/site-packages/pymysql/protocol.py", line 221, in raise_for_error
    err.raise_mysql_exception(self._data)
  File "/Users/user/Documents/python/AstreinteFinale/venv/lib/python3.10/site-packages/pymysql/err.py", line 143, in raise_mysql_exception
    raise errorclass(errno, errval)
sqlalchemy.exc.OperationalError: (pymysql.err.OperationalError) (1364, "Field 'id' doesn't have a default value")
[SQL: INSERT INTO historique (astreinte_id, date_debut, date_fin) VALUES (%(astreinte_id)s, %(date_debut)s, %(date_fin)s)]
[parameters: {'astreinte_id': 1, 'date_debut': datetime.datetime(2022, 1, 3, 12, 10, 10), 'date_fin': datetime.datetime(2022, 1, 3, 12, 20, 3)}]
(Background on this error at: https://sqlalche.me/e/14/e3q8)
127.0.0.1 - - [03/Jan/2022 12:22:20] "[35m[1mGET /astreintes HTTP/1.1[0m" 500 -
Traceback (most recent call last):
  File "/Users/user/Documents/python/AstreinteFinale/venv/lib/python3.10/site-packages/sqlalchemy/engine/base.py", line 1802, in _execute_context
    self.dialect.do_execute(
  File "/Users/user/Documents/python/AstreinteFinale/venv/lib/python3.10/site-packages/sqlalchemy/engine/default.py", line 732, in do_execute
    cursor.execute(statement, parameters)
  File "/Users/user/Documents/python/AstreinteFinale/venv/lib/python3.10/site-packages/pymysql/cursors.py", line 148, in execute
    result = self._query(query)
  File "/Users/user/Documents/python/AstreinteFinale/venv/lib/python3.10/site-packages/pymysql/cursors.py", line 310, in _query
    conn.query(q)
  File "/Users/user/Documents/python/AstreinteFinale/venv/lib/python3.10/site-packages/pymysql/connections.py", line 548, in query
    self._affected_rows = self._read_query_result(unbuffered=unbuffered)
  File "/Users/user/Documents/python/AstreinteFinale/venv/lib/python3.10/site-packages/pymysql/connections.py", line 775, in _read_query_result
    result.read()
  File "/Users/user/Documents/python/AstreinteFinale/venv/lib/python3.10/site-packages/pymysql/connections.py", line 1156, in read
    first_packet = self.connection._read_packet()
  File "/Users/user/Documents/python/AstreinteFinale/venv/lib/python3.10/site-packages/pymysql/connections.py", line 725, in _read_packet
    packet.raise_for_error()
  File "/Users/user/Documents/python/AstreinteFinale/venv/lib/python3.10/site-packages/pymysql/protocol.py", line 221, in raise_for_error
    err.raise_mysql_exception(self._data)
  File "/Users/user/Documents/python/AstreinteFinale/venv/lib/python3.10/site-packages/pymysql/err.py", line 143, in raise_mysql_exception
    raise errorclass(errno, errval)
pymysql.err.OperationalError: (1364, "Field 'id' doesn't have a default value")

The above exception was the direct cause of the following exception:

Traceback (most recent call last):
  File "/Users/user/Documents/python/AstreinteFinale/venv/lib/python3.10/site-packages/flask/app.py", line 2091, in __call__
    return self.wsgi_app(environ, start_response)
  File "/Users/user/Documents/python/AstreinteFinale/venv/lib/python3.10/site-packages/flask/app.py", line 2076, in wsgi_app
    response = self.handle_exception(e)
  File "/Users/user/Documents/python/AstreinteFinale/venv/lib/python3.10/site-packages/flask/app.py", line 2073, in wsgi_app
    response = self.full_dispatch_request()
  File "/Users/user/Documents/python/AstreinteFinale/venv/lib/python3.10/site-packages/flask/app.py", line 1518, in full_dispatch_request
    rv = self.handle_user_exception(e)
  File "/Users/user/Documents/python/AstreinteFinale/venv/lib/python3.10/site-packages/flask/app.py", line 1516, in full_dispatch_request
    rv = self.dispatch_request()
  File "/Users/user/Documents/python/AstreinteFinale/venv/lib/python3.10/site-packages/flask/app.py", line 1502, in dispatch_request
    return self.ensure_sync(self.view_functions[rule.endpoint])(**req.view_args)
  File "/Users/user/Documents/python/AstreinteFinale/base.py", line 274, in send
    Commite(historique)
  File "/Users/user/Documents/python/AstreinteFinale/base.py", line 378, in Commite
    db.session.commit()
  File "<string>", line 2, in commit
    
  File "/Users/user/Documents/python/AstreinteFinale/venv/lib/python3.10/site-packages/sqlalchemy/orm/session.py", line 1431, in commit
    self._transaction.commit(_to_root=self.future)
  File "/Users/user/Documents/python/AstreinteFinale/venv/lib/python3.10/site-packages/sqlalchemy/orm/session.py", line 829, in commit
    self._prepare_impl()
  File "/Users/user/Documents/python/AstreinteFinale/venv/lib/python3.10/site-packages/sqlalchemy/orm/session.py", line 808, in _prepare_impl
    self.session.flush()
  File "/Users/user/Documents/python/AstreinteFinale/venv/lib/python3.10/site-packages/sqlalchemy/orm/session.py", line 3363, in flush
    self._flush(objects)
  File "/Users/user/Documents/python/AstreinteFinale/venv/lib/python3.10/site-packages/sqlalchemy/orm/session.py", line 3502, in _flush
    with util.safe_reraise():
  File "/Users/user/Documents/python/AstreinteFinale/venv/lib/python3.10/site-packages/sqlalchemy/util/langhelpers.py", line 70, in __exit__
    compat.raise_(
  File "/Users/user/Documents/python/AstreinteFinale/venv/lib/python3.10/site-packages/sqlalchemy/util/compat.py", line 207, in raise_
    raise exception
  File "/Users/user/Documents/python/AstreinteFinale/venv/lib/python3.10/site-packages/sqlalchemy/orm/session.py", line 3463, in _flush
    flush_context.execute()
  File "/Users/user/Documents/python/AstreinteFinale/venv/lib/python3.10/site-packages/sqlalchemy/orm/unitofwork.py", line 456, in execute
    rec.execute(self)
  File "/Users/user/Documents/python/AstreinteFinale/venv/lib/python3.10/site-packages/sqlalchemy/orm/unitofwork.py", line 630, in execute
    util.preloaded.orm_persistence.save_obj(
  File "/Users/user/Documents/python/AstreinteFinale/venv/lib/python3.10/site-packages/sqlalchemy/orm/persistence.py", line 244, in save_obj
    _emit_insert_statements(
  File "/Users/user/Documents/python/AstreinteFinale/venv/lib/python3.10/site-packages/sqlalchemy/orm/persistence.py", line 1221, in _emit_insert_statements
    result = connection._execute_20(
  File "/Users/user/Documents/python/AstreinteFinale/venv/lib/python3.10/site-packages/sqlalchemy/engine/base.py", line 1614, in _execute_20
    return meth(self, args_10style, kwargs_10style, execution_options)
  File "/Users/user/Documents/python/AstreinteFinale/venv/lib/python3.10/site-packages/sqlalchemy/sql/elements.py", line 325, in _execute_on_connection
    return connection._execute_clauseelement(
  File "/Users/user/Documents/python/AstreinteFinale/venv/lib/python3.10/site-packages/sqlalchemy/engine/base.py", line 1481, in _execute_clauseelement
    ret = self._execute_context(
  File "/Users/user/Documents/python/AstreinteFinale/venv/lib/python3.10/site-packages/sqlalchemy/engine/base.py", line 1845, in _execute_context
    self._handle_dbapi_exception(
  File "/Users/user/Documents/python/AstreinteFinale/venv/lib/python3.10/site-packages/sqlalchemy/engine/base.py", line 2026, in _handle_dbapi_exception
    util.raise_(
  File "/Users/user/Documents/python/AstreinteFinale/venv/lib/python3.10/site-packages/sqlalchemy/util/compat.py", line 207, in raise_
    raise exception
  File "/Users/user/Documents/python/AstreinteFinale/venv/lib/python3.10/site-packages/sqlalchemy/engine/base.py", line 1802, in _execute_context
    self.dialect.do_execute(
  File "/Users/user/Documents/python/AstreinteFinale/venv/lib/python3.10/site-packages/sqlalchemy/engine/default.py", line 732, in do_execute
    cursor.execute(statement, parameters)
  File "/Users/user/Documents/python/AstreinteFinale/venv/lib/python3.10/site-packages/pymysql/cursors.py", line 148, in execute
    result = self._query(query)
  File "/Users/user/Documents/python/AstreinteFinale/venv/lib/python3.10/site-packages/pymysql/cursors.py", line 310, in _query
    conn.query(q)
  File "/Users/user/Documents/python/AstreinteFinale/venv/lib/python3.10/site-packages/pymysql/connections.py", line 548, in query
    self._affected_rows = self._read_query_result(unbuffered=unbuffered)
  File "/Users/user/Documents/python/AstreinteFinale/venv/lib/python3.10/site-packages/pymysql/connections.py", line 775, in _read_query_result
    result.read()
  File "/Users/user/Documents/python/AstreinteFinale/venv/lib/python3.10/site-packages/pymysql/connections.py", line 1156, in read
    first_packet = self.connection._read_packet()
  File "/Users/user/Documents/python/AstreinteFinale/venv/lib/python3.10/site-packages/pymysql/connections.py", line 725, in _read_packet
    packet.raise_for_error()
  File "/Users/user/Documents/python/AstreinteFinale/venv/lib/python3.10/site-packages/pymysql/protocol.py", line 221, in raise_for_error
    err.raise_mysql_exception(self._data)
  File "/Users/user/Documents/python/AstreinteFinale/venv/lib/python3.10/site-packages/pymysql/err.py", line 143, in raise_mysql_exception
    raise errorclass(errno, errval)
sqlalchemy.exc.OperationalError: (pymysql.err.OperationalError) (1364, "Field 'id' doesn't have a default value")
[SQL: INSERT INTO historique (astreinte_id, date_debut, date_fin) VALUES (%(astreinte_id)s, %(date_debut)s, %(date_fin)s)]
[parameters: {'astreinte_id': 1, 'date_debut': datetime.datetime(2022, 1, 3, 12, 10, 10), 'date_fin': datetime.datetime(2022, 1, 3, 12, 22, 10)}]
(Background on this error at: https://sqlalche.me/e/14/e3q8)
 * Serving Flask app 'base' (lazy loading)
 * Environment: production
   WARNING: This is a development server. Do not use it in a production deployment.
   Use a production WSGI server instead.
 * Debug mode: on
Traceback (most recent call last):
  File "/Users/user/Documents/python/AstreinteFinale/base.py", line 417, in <module>
    app.run(debug=True, host="127.0.0.1",port=500)
  File "/Users/user/Documents/python/AstreinteFinale/venv/lib/python3.10/site-packages/flask/app.py", line 920, in run
    run_simple(t.cast(str, host), port, self, **options)
  File "/Users/user/Documents/python/AstreinteFinale/venv/lib/python3.10/site-packages/werkzeug/serving.py", line 984, in run_simple
    s.bind(server_address)
PermissionError: [Errno 13] Permission denied
 * Detected change in '/Users/user/Documents/python/AstreinteFinale/base.py', reloading
 * Detected change in '/Users/user/Documents/python/AstreinteFinale/base.py', reloading
 * Restarting with stat
 * Restarting with stat
 * Serving Flask app 'base' (lazy loading)
 * Serving Flask app 'base' (lazy loading)
 * Environment: production
 * Environment: production
   WARNING: This is a development server. Do not use it in a production deployment.
   WARNING: This is a development server. Do not use it in a production deployment.
   Use a production WSGI server instead.
 * Debug mode: on
   Use a production WSGI server instead.
 * Debug mode: on
 * Debugger is active!
 * Debugger is active!
 * Debugger PIN: 655-285-932
 * Debugger PIN: 655-285-932
Traceback (most recent call last):
Traceback (most recent call last):
  File "/Users/user/Documents/python/AstreinteFinale/base.py", line 417, in <module>
  File "/Users/user/Documents/python/AstreinteFinale/base.py", line 417, in <module>
    app.run(debug=True, host="127.0.0.1",port=5000)
  File "/Users/user/Documents/python/AstreinteFinale/venv/lib/python3.10/site-packages/flask/app.py", line 920, in run
    app.run(debug=True, host="127.0.0.1",port=5000)
  File "/Users/user/Documents/python/AstreinteFinale/venv/lib/python3.10/site-packages/flask/app.py", line 920, in run
    run_simple(t.cast(str, host), port, self, **options)
    run_simple(t.cast(str, host), port, self, **options)
  File "/Users/user/Documents/python/AstreinteFinale/venv/lib/python3.10/site-packages/werkzeug/serving.py", line 984, in run_simple
  File "/Users/user/Documents/python/AstreinteFinale/venv/lib/python3.10/site-packages/werkzeug/serving.py", line 984, in run_simple
    s.bind(server_address)
    s.bind(server_address)
PermissionError: [Errno 13] Permission denied
PermissionError: [Errno 13] Permission denied
